Workbook

Sheet Start
A1: Kursmappe (Oberstufe) · Vorlage v15.2
B3: SCHNELL ZU DEN BLÄTTERN:
B4: =HYPERLINK("#'Klassenliste'!A1","Klassenliste") | C4: =HYPERLINK("#'Sitzplan'!A1","Sitzplan") | D4: =HYPERLINK("#'Anw 1.HJ'!A1","Anw 1.HJ") | E4: =HYPERLINK("#'Mat 1.HJ'!A1","Mat 1.HJ")
B5: =HYPERLINK("#'Noten 1.HJ'!A1","Noten 1.HJ") | C5: =HYPERLINK("#'Anw 2.HJ'!A1","Anw 2.HJ") | D5: =HYPERLINK("#'Mat 2.HJ'!A1","Mat 2.HJ") | E5: =HYPERLINK("#'Noten 2.HJ'!A1","Noten 2.HJ")
B6: =HYPERLINK("#'Verspätung'!A1","Verspätung") | C6: =HYPERLINK("#'KA1'!A1","KA1") | D6: =HYPERLINK("#'KA2'!A1","KA2") | E6: =HYPERLINK("#'KA3'!A1","KA3")
B7: =HYPERLINK("#'KA4'!A1","KA4") | C7: =HYPERLINK("#'KA5'!A1","KA5") | D7: =HYPERLINK("#'KA6'!A1","KA6") | E7: =HYPERLINK("#'Notentabelle'!A1","Notentabelle")
B8: =HYPERLINK("#'Rückmeldebogen'!A1","Rückmeldebogen")
B10: NEUES SCHULJAHR IN 3 SCHRITTEN:
B11: 1. Diese Datei kopieren und umbenennen, z. B. "Klassenmappe 5b 2026-27.xlsx".
B12: 2. Blatt "Klassenliste": Kopfzeile und Namen eintragen.
B13: 3. Fertig. Alle anderen Blätter füllen sich selbst aus der Klassenliste.
B15: SCHÜLERZAHL:
B16: • Platz für bis zu 35 Schüler/innen. Weniger? Einfach weniger Namen eintragen —
B17: leere Zeilen blenden sich auf allen Blättern automatisch aus.
B18: • Zeilen NIE löschen oder einfügen — zum Entfernen den Namen leeren.
B20: SORTIEREN & REIHENFOLGE:
B21: • Die Zeilen-Reihenfolge der Klassenliste ist die Identität: alle Einträge auf den anderen
B22: Blättern hängen an der Zeilennummer. Darum hat die Klassenliste eine SORTIER-AMPEL (Zeile 4):
B23: • GRÜN = andere Blätter noch leer: B6:D40 markieren → Daten → Sortieren — gefahrlos,
... B63: Vorlage v15.2 · 2026-09-30 · Notengrenzen = amtliche Zentralabitur-Tabelle NRW

Sheet Klassenliste
A1: Kursliste | L1: =HYPERLINK("#Start!A1","⌂")
B2: Schuljahr: | D2: Kurs: | F2: Lehrkraft: | I2: Fach:
B3: leere Zeilen blenden sich automatisch aus · Neuzugänge unten anhängen (wie im Papier-Klassenbuch)
B4: =IF($AA$4=0,"✓ Sortieren möglich — B6:D40 markieren","✗ Nicht sortieren — "&$AA$4&" Einträge") | E4: 1. Halbjahr | G4: 2. Halbjahr | I4: Fehlzeiten (FS · davon uE) | AA4: =COUNTA(KA1!$D$8:$O$42)+COUNTA(KA2!$D$8:$O$42)+COUNTA(KA3!$D$8:$O$42)+COUNTA(KA4!$D$8:$O$42)+COUNTA(KA5!$D$8:$O$42)+COUNTA(KA6!$D$8:$O$42)+COUNTA('Noten 1.HJ'!$J$7:$O$41)+COUNTA('Noten 1.HJ'!$T$7:$Y$41)+COUNTA('Anw 1.HJ'!$F$6:$AI$40)+COUNTA('Mat 1.HJ'!$G$6:$AJ$40)+COUNTA('Noten 2.HJ'!$J$7:$O$41)+COUNTA('Noten 2.HJ'!$T$7:$Y$41)+COUNTA('Anw 2.HJ'!$F$6:$AI$40)+COUNTA('Mat 2.HJ'!$G$6:$AJ$40)+COUNTA('Verspätung'!$F$6:$AS$40)+COUNTA(Sitzplan!$B$4:$M$14)
A5: Nr | B5: Name | C5: Vorname | D5: Notiz | E5: Pkt | F5: Note | G5: Pkt | H5: Note | I5: 1.HJ | J5: uE | K5: 2.HJ | L5: uE
A6: 1 | E6: =IF($B6="","",INDEX('Noten 1.HJ'!$AA$7:$AA$41,$A6)) | F6: =IF($B6="","",INDEX('Noten 1.HJ'!$AB$7:$AB$41,$A6)) | G6: =IF($B6="","",INDEX('Noten 2.HJ'!$AA$7:$AA$41,$A6)) | H6: =IF($B6="","",INDEX('Noten 2.HJ'!$AB$7:$AB$41,$A6)) | I6: =IF($B6="","",INDEX('Anw 1.HJ'!$D$6:$D$40,$A6)) | J6: =IF($B6="","",INDEX('Anw 1.HJ'!$E$6:$E$40,$A6)) | K6: =IF($B6="","",INDEX('Anw 2.HJ'!$D$6:$D$40,$A6)) | L6: =IF($B6="","",INDEX('Anw 2.HJ'!$E$6:$E$40,$A6))
A7: 2 | E7: =IF($B7="","",INDEX('Noten 1.HJ'!$AA$7:$AA$41,$A7)) | F7: =IF($B7="","",INDEX('Noten 1.HJ'!$AB$7:$AB$41,$A7)) | G7: =IF($B7="","",INDEX('Noten 2.HJ'!$AA$7:$AA$41,$A7)) | H7: =IF($B7="","",INDEX('Noten 2.HJ'!$AB$7:$AB$41,$A7)) | I7: =IF($B7="","",INDEX('Anw 1.HJ'!$D$6:$D$40,$A7)) | J7: =IF($B7="","",INDEX('Anw 1.HJ'!$E$6:$E$40,$A7)) | K7: =IF($B7="","",INDEX('Anw 2.HJ'!$D$6:$D$40,$A7)) | L7: =IF($B7="","",INDEX('Anw 2.HJ'!$E$6:$E$40,$A7))
A8: 3 | E8: =IF($B8="","",INDEX('Noten 1.HJ'!$AA$7:$AA$41,$A8)) | F8: =IF($B8="","",INDEX('Noten 1.HJ'!$AB$7:$AB$41,$A8)) | G8: =IF($B8="","",INDEX('Noten 2.HJ'!$AA$7:$AA$41,$A8)) | H8: =IF($B8="","",INDEX('Noten 2.HJ'!$AB$7:$AB$41,$A8)) | I8: =IF($B8="","",INDEX('Anw 1.HJ'!$D$6:$D$40,$A8)) | J8: =IF($B8="","",INDEX('Anw 1.HJ'!$E$6:$E$40,$A8)) | K8: =IF($B8="","",INDEX('Anw 2.HJ'!$D$6:$D$40,$A8)) | L8: =IF($B8="","",INDEX('Anw 2.HJ'!$E$6:$E$40,$A8))
A9: 4 | E9: =IF($B9="","",INDEX('Noten 1.HJ'!$AA$7:$AA$41,$A9)) | F9: =IF($B9="","",INDEX('Noten 1.HJ'!$AB$7:$AB$41,$A9)) | G9: =IF($B9="","",INDEX('Noten 2.HJ'!$AA$7:$AA$41,$A9)) | H9: =IF($B9="","",INDEX('Noten 2.HJ'!$AB$7:$AB$41,$A9)) | I9: =IF($B9="","",INDEX('Anw 1.HJ'!$D$6:$D$40,$A9)) | J9: =IF($B9="","",INDEX('Anw 1.HJ'!$E$6:$E$40,$A9)) | K9: =IF($B9="","",INDEX('Anw 2.HJ'!$D$6:$D$40,$A9)) | L9: =IF($B9="","",INDEX('Anw 2.HJ'!$E$6:$E$40,$A9))
A10: 5 | E10: =IF($B10="","",INDEX('Noten 1.HJ'!$AA$7:$AA$41,$A10)) | F10: =IF($B10="","",INDEX('Noten 1.HJ'!$AB$7:$AB$41,$A10)) | G10: =IF($B10="","",INDEX('Noten 2.HJ'!$AA$7:$AA$41,$A10)) | H10: =IF($B10="","",INDEX('Noten 2.HJ'!$AB$7:$AB$41,$A10)) | I10: =IF($B10="","",INDEX('Anw 1.HJ'!$D$6:$D$40,$A10)) | J10: =IF($B10="","",INDEX('Anw 1.HJ'!$E$6:$E$40,$A10)) | K10: =IF($B10="","",INDEX('Anw 2.HJ'!$D$6:$D$40,$A10)) | L10: =IF($B10="","",INDEX('Anw 2.HJ'!$E$6:$E$40,$A10))
A11: 6 | E11: =IF($B11="","",INDEX('Noten 1.HJ'!$AA$7:$AA$41,$A11)) | F11: =IF($B11="","",INDEX('Noten 1.HJ'!$AB$7:$AB$41,$A11)) | G11: =IF($B11="","",INDEX('Noten 2.HJ'!$AA$7:$AA$41,$A11)) | H11: =IF($B11="","",INDEX('Noten 2.HJ'!$AB$7:$AB$41,$A11)) | I11: =IF($B11="","",INDEX('Anw 1.HJ'!$D$6:$D$40,$A11)) | J11: =IF($B11="","",INDEX('Anw 1.HJ'!$E$6:$E$40,$A11)) | K11: =IF($B11="","",INDEX('Anw 2.HJ'!$D$6:$D$40,$A11)) | L11: =IF($B11="","",INDEX('Anw 2.HJ'!$E$6:$E$40,$A11))
A12: 7 | E12: =IF($B12="","",INDEX('Noten 1.HJ'!$AA$7:$AA$41,$A12)) | F12: =IF($B12="","",INDEX('Noten 1.HJ'!$AB$7:$AB$41,$A12)) | G12: =IF($B12="","",INDEX('Noten 2.HJ'!$AA$7:$AA$41,$A12)) | H12: =IF($B12="","",INDEX('Noten 2.HJ'!$AB$7:$AB$41,$A12)) | I12: =IF($B12="","",INDEX('Anw 1.HJ'!$D$6:$D$40,$A12)) | J12: =IF($B12="","",INDEX('Anw 1.HJ'!$E$6:$E$40,$A12)) | K12: =IF($B12="","",INDEX('Anw 2.HJ'!$D$6:$D$40,$A12)) | L12: =IF($B12="","",INDEX('Anw 2.HJ'!$E$6:$E$40,$A12))
A13: 8 | E13: =IF($B13="","",INDEX('Noten 1.HJ'!$AA$7:$AA$41,$A13)) | F13: =IF($B13="","",INDEX('Noten 1.HJ'!$AB$7:$AB$41,$A13)) | G13: =IF($B13="","",INDEX('Noten 2.HJ'!$AA$7:$AA$41,$A13)) | H13: =IF($B13="","",INDEX('Noten 2.HJ'!$AB$7:$AB$41,$A13)) | I13: =IF($B13="","",INDEX('Anw 1.HJ'!$D$6:$D$40,$A13)) | J13: =IF($B13="","",INDEX('Anw 1.HJ'!$E$6:$E$40,$A13)) | K13: =IF($B13="","",INDEX('Anw 2.HJ'!$D$6:$D$40,$A13)) | L13: =IF($B13="","",INDEX('Anw 2.HJ'!$E$6:$E$40,$A13))
A14: 9 | E14: =IF($B14="","",INDEX('Noten 1.HJ'!$AA$7:$AA$41,$A14)) | F14: =IF($B14="","",INDEX('Noten 1.HJ'!$AB$7:$AB$41,$A14)) | G14: =IF($B14="","",INDEX('Noten 2.HJ'!$AA$7:$AA$41,$A14)) | H14: =IF($B14="","",INDEX('Noten 2.HJ'!$AB$7:$AB$41,$A14)) | I14: =IF($B14="","",INDEX('Anw 1.HJ'!$D$6:$D$40,$A14)) | J14: =IF($B14="","",INDEX('Anw 1.HJ'!$E$6:$E$40,$A14)) | K14: =IF($B14="","",INDEX('Anw 2.HJ'!$D$6:$D$40,$A14)) | L14: =IF($B14="","",INDEX('Anw 2.HJ'!$E$6:$E$40,$A14))
A15: 10 | E15: =IF($B15="","",INDEX('Noten 1.HJ'!$AA$7:$AA$41,$A15)) | F15: =IF($B15="","",INDEX('Noten 1.HJ'!$AB$7:$AB$41,$A15)) | G15: =IF($B15="","",INDEX('Noten 2.HJ'!$AA$7:$AA$41,$A15)) | H15: =IF($B15="","",INDEX('Noten 2.HJ'!$AB$7:$AB$41,$A15)) | I15: =IF($B15="","",INDEX('Anw 1.HJ'!$D$6:$D$40,$A15)) | J15: =IF($B15="","",INDEX('Anw 1.HJ'!$E$6:$E$40,$A15)) | K15: =IF($B15="","",INDEX('Anw 2.HJ'!$D$6:$D$40,$A15)) | L15: =IF($B15="","",INDEX('Anw 2.HJ'!$E$6:$E$40,$A15))
A16: 11 | E16: =IF($B16="","",INDEX('Noten 1.HJ'!$AA$7:$AA$41,$A16)) | F16: =IF($B16="","",INDEX('Noten 1.HJ'!$AB$7:$AB$41,$A16)) | G16: =IF($B16="","",INDEX('Noten 2.HJ'!$AA$7:$AA$41,$A16)) | H16: =IF($B16="","",INDEX('Noten 2.HJ'!$AB$7:$AB$41,$A16)) | I16: =IF($B16="","",INDEX('Anw 1.HJ'!$D$6:$D$40,$A16)) | J16: =IF($B16="","",INDEX('Anw 1.HJ'!$E$6:$E$40,$A16)) | K16: =IF($B16="","",INDEX('Anw 2.HJ'!$D$6:$D$40,$A16)) | L16: =IF($B16="","",INDEX('Anw 2.HJ'!$E$6:$E$40,$A16))
A17: 12 | E17: =IF($B17="","",INDEX('Noten 1.HJ'!$AA$7:$AA$41,$A17)) | F17: =IF($B17="","",INDEX('Noten 1.HJ'!$AB$7:$AB$41,$A17)) | G17: =IF($B17="","",INDEX('Noten 2.HJ'!$AA$7:$AA$41,$A17)) | H17: =IF($B17="","",INDEX('Noten 2.HJ'!$AB$7:$AB$41,$A17)) | I17: =IF($B17="","",INDEX('Anw 1.HJ'!$D$6:$D$40,$A17)) | J17: =IF($B17="","",INDEX('Anw 1.HJ'!$E$6:$E$40,$A17)) | K17: =IF($B17="","",INDEX('Anw 2.HJ'!$D$6:$D$40,$A17)) | L17: =IF($B17="","",INDEX('Anw 2.HJ'!$E$6:$E$40,$A17))
... A40: 35 | E40: =IF($B40="","",INDEX('Noten 1.HJ'!$AA$7:$AA$41,$A40)) | F40: =IF($B40="","",INDEX('Noten 1.HJ'!$AB$7:$AB$41,$A40)) | G40: =IF($B40="","",INDEX('Noten 2.HJ'!$AA$7:$AA$41,$A40)) | H40: =IF($B40="","",INDEX('Noten 2.HJ'!$AB$7:$AB$41,$A40)) | I40: =IF($B40="","",INDEX('Anw 1.HJ'!$D$6:$D$40,$A40)) | J40: =IF($B40="","",INDEX('Anw 1.HJ'!$E$6:$E$40,$A40)) | K40: =IF($B40="","",INDEX('Anw 2.HJ'!$D$6:$D$40,$A40)) | L40: =IF($B40="","",INDEX('Anw 2.HJ'!$E$6:$E$40,$A40))

Sheet Sitzplan
A1: Sitzplan | M1: =HYPERLINK("#Start!A1","⌂")
B2: Klasse: | C2: =Klassenliste!$E$2&"" | D2: Raum: | F2: gültig ab: | J2: Lehrkraft: | L2: =Klassenliste!$H$2&""
B3: Quadrat anklicken → Schüler wählen · leere Quadrate = Lücken/Gänge · Tafel/Pult unten (vorne)
AA4: (Rechen-Hilfsspalte für Dropdown + Liste)
AA5: =IF(INDEX(Klassenliste!$B$6:$B$40,1)=0,"",1&" "&INDEX(Klassenliste!$C$6:$C$40,1)&" "&LEFT(INDEX(Klassenliste!$B$6:$B$40,1),1)&".")
AA6: =IF(INDEX(Klassenliste!$B$6:$B$40,2)=0,"",2&" "&INDEX(Klassenliste!$C$6:$C$40,2)&" "&LEFT(INDEX(Klassenliste!$B$6:$B$40,2),1)&".")
AA7: =IF(INDEX(Klassenliste!$B$6:$B$40,3)=0,"",3&" "&INDEX(Klassenliste!$C$6:$C$40,3)&" "&LEFT(INDEX(Klassenliste!$B$6:$B$40,3),1)&".")
AA8: =IF(INDEX(Klassenliste!$B$6:$B$40,4)=0,"",4&" "&INDEX(Klassenliste!$C$6:$C$40,4)&" "&LEFT(INDEX(Klassenliste!$B$6:$B$40,4),1)&".")
AA9: =IF(INDEX(Klassenliste!$B$6:$B$40,5)=0,"",5&" "&INDEX(Klassenliste!$C$6:$C$40,5)&" "&LEFT(INDEX(Klassenliste!$B$6:$B$40,5),1)&".")
AA10: =IF(INDEX(Klassenliste!$B$6:$B$40,6)=0,"",6&" "&INDEX(Klassenliste!$C$6:$C$40,6)&" "&LEFT(INDEX(Klassenliste!$B$6:$B$40,6),1)&".")
AA11: =IF(INDEX(Klassenliste!$B$6:$B$40,7)=0,"",7&" "&INDEX(Klassenliste!$C$6:$C$40,7)&" "&LEFT(INDEX(Klassenliste!$B$6:$B$40,7),1)&".")
AA12: =IF(INDEX(Klassenliste!$B$6:$B$40,8)=0,"",8&" "&INDEX(Klassenliste!$C$6:$C$40,8)&" "&LEFT(INDEX(Klassenliste!$B$6:$B$40,8),1)&".")
AA13: =IF(INDEX(Klassenliste!$B$6:$B$40,9)=0,"",9&" "&INDEX(Klassenliste!$C$6:$C$40,9)&" "&LEFT(INDEX(Klassenliste!$B$6:$B$40,9),1)&".")
AA14: =IF(INDEX(Klassenliste!$B$6:$B$40,10)=0,"",10&" "&INDEX(Klassenliste!$C$6:$C$40,10)&" "&LEFT(INDEX(Klassenliste!$B$6:$B$40,10),1)&".")
AA15: =IF(INDEX(Klassenliste!$B$6:$B$40,11)=0,"",11&" "&INDEX(Klassenliste!$C$6:$C$40,11)&" "&LEFT(INDEX(Klassenliste!$B$6:$B$40,11),1)&".")
G16: P U L T | AA16: =IF(INDEX(Klassenliste!$B$6:$B$40,12)=0,"",12&" "&INDEX(Klassenliste!$C$6:$C$40,12)&" "&LEFT(INDEX(Klassenliste!$B$6:$B$40,12),1)&".")
F17: T A F E L | AA17: =IF(INDEX(Klassenliste!$B$6:$B$40,13)=0,"",13&" "&INDEX(Klassenliste!$C$6:$C$40,13)&" "&LEFT(INDEX(Klassenliste!$B$6:$B$40,13),1)&".")
AA18: =IF(INDEX(Klassenliste!$B$6:$B$40,14)=0,"",14&" "&INDEX(Klassenliste!$C$6:$C$40,14)&" "&LEFT(INDEX(Klassenliste!$B$6:$B$40,14),1)&".")
B19: Schülerliste (zum Auslosen): | AA19: =IF(INDEX(Klassenliste!$B$6:$B$40,15)=0,"",15&" "&INDEX(Klassenliste!$C$6:$C$40,15)&" "&LEFT(INDEX(Klassenliste!$B$6:$B$40,15),1)&".")
B20: =IF(AA5="","",AA5) | D20: =IF(AA6="","",AA6) | F20: =IF(AA7="","",AA7) | H20: =IF(AA8="","",AA8) | J20: =IF(AA9="","",AA9) | L20: =IF(AA10="","",AA10) | AA20: =IF(INDEX(Klassenliste!$B$6:$B$40,16)=0,"",16&" "&INDEX(Klassenliste!$C$6:$C$40,16)&" "&LEFT(INDEX(Klassenliste!$B$6:$B$40,16),1)&".")
B21: =IF(AA11="","",AA11) | D21: =IF(AA12="","",AA12) | F21: =IF(AA13="","",AA13) | H21: =IF(AA14="","",AA14) | J21: =IF(AA15="","",AA15) | L21: =IF(AA16="","",AA16) | AA21: =IF(INDEX(Klassenliste!$B$6:$B$40,17)=0,"",17&" "&INDEX(Klassenliste!$C$6:$C$40,17)&" "&LEFT(INDEX(Klassenliste!$B$6:$B$40,17),1)&".")
B22: =IF(AA17="","",AA17) | D22: =IF(AA18="","",AA18) | F22: =IF(AA19="","",AA19) | H22: =IF(AA20="","",AA20) | J22: =IF(AA21="","",AA21) | L22: =IF(AA22="","",AA22) | AA22: =IF(INDEX(Klassenliste!$B$6:$B$40,18)=0,"",18&" "&INDEX(Klassenliste!$C$6:$C$40,18)&" "&LEFT(INDEX(Klassenliste!$B$6:$B$40,18),1)&".")
B23: =IF(AA23="","",AA23) | D23: =IF(AA24="","",AA24) | F23: =IF(AA25="","",AA25) | H23: =IF(AA26="","",AA26) | J23: =IF(AA27="","",AA27) | L23: =IF(AA28="","",AA28) | AA23: =IF(INDEX(Klassenliste!$B$6:$B$40,19)=0,"",19&" "&INDEX(Klassenliste!$C$6:$C$40,19)&" "&LEFT(INDEX(Klassenliste!$B$6:$B$40,19),1)&".")
B24: =IF(AA29="","",AA29) | D24: =IF(AA30="","",AA30) | F24: =IF(AA31="","",AA31) | H24: =IF(AA32="","",AA32) | J24: =IF(AA33="","",AA33) | L24: =IF(AA34="","",AA34) | AA24: =IF(INDEX(Klassenliste!$B$6:$B$40,20)=0,"",20&" "&INDEX(Klassenliste!$C$6:$C$40,20)&" "&LEFT(INDEX(Klassenliste!$B$6:$B$40,20),1)&".")
B25: =IF(AA35="","",AA35) | D25: =IF(AA36="","",AA36) | F25: =IF(AA37="","",AA37) | H25: =IF(AA38="","",AA38) | J25: =IF(AA39="","",AA39) | AA25: =IF(INDEX(Klassenliste!$B$6:$B$40,21)=0,"",21&" "&INDEX(Klassenliste!$C$6:$C$40,21)&" "&LEFT(INDEX(Klassenliste!$B$6:$B$40,21),1)&".")
AA26: =IF(INDEX(Klassenliste!$B$6:$B$40,22)=0,"",22&" "&INDEX(Klassenliste!$C$6:$C$40,22)&" "&LEFT(INDEX(Klassenliste!$B$6:$B$40,22),1)&".")
AA27: =IF(INDEX(Klassenliste!$B$6:$B$40,23)=0,"",23&" "&INDEX(Klassenliste!$C$6:$C$40,23)&" "&LEFT(INDEX(Klassenliste!$B$6:$B$40,23),1)&".")
AA28: =IF(INDEX(Klassenliste!$B$6:$B$40,24)=0,"",24&" "&INDEX(Klassenliste!$C$6:$C$40,24)&" "&LEFT(INDEX(Klassenliste!$B$6:$B$40,24),1)&".")
AA29: =IF(INDEX(Klassenliste!$B$6:$B$40,25)=0,"",25&" "&INDEX(Klassenliste!$C$6:$C$40,25)&" "&LEFT(INDEX(Klassenliste!$B$6:$B$40,25),1)&".")
AA30: =IF(INDEX(Klassenliste!$B$6:$B$40,26)=0,"",26&" "&INDEX(Klassenliste!$C$6:$C$40,26)&" "&LEFT(INDEX(Klassenliste!$B$6:$B$40,26),1)&".")
AA31: =IF(INDEX(Klassenliste!$B$6:$B$40,27)=0,"",27&" "&INDEX(Klassenliste!$C$6:$C$40,27)&" "&LEFT(INDEX(Klassenliste!$B$6:$B$40,27),1)&".")
AA32: =IF(INDEX(Klassenliste!$B$6:$B$40,28)=0,"",28&" "&INDEX(Klassenliste!$C$6:$C$40,28)&" "&LEFT(INDEX(Klassenliste!$B$6:$B$40,28),1)&".")
AA33: =IF(INDEX(Klassenliste!$B$6:$B$40,29)=0,"",29&" "&INDEX(Klassenliste!$C$6:$C$40,29)&" "&LEFT(INDEX(Klassenliste!$B$6:$B$40,29),1)&".")
AA34: =IF(INDEX(Klassenliste!$B$6:$B$40,30)=0,"",30&" "&INDEX(Klassenliste!$C$6:$C$40,30)&" "&LEFT(INDEX(Klassenliste!$B$6:$B$40,30),1)&".")
AA35: =IF(INDEX(Klassenliste!$B$6:$B$40,31)=0,"",31&" "&INDEX(Klassenliste!$C$6:$C$40,31)&" "&LEFT(INDEX(Klassenliste!$B$6:$B$40,31),1)&".")
AA36: =IF(INDEX(Klassenliste!$B$6:$B$40,32)=0,"",32&" "&INDEX(Klassenliste!$C$6:$C$40,32)&" "&LEFT(INDEX(Klassenliste!$B$6:$B$40,32),1)&".")
AA37: =IF(INDEX(Klassenliste!$B$6:$B$40,33)=0,"",33&" "&INDEX(Klassenliste!$C$6:$C$40,33)&" "&LEFT(INDEX(Klassenliste!$B$6:$B$40,33),1)&".")
AA38: =IF(INDEX(Klassenliste!$B$6:$B$40,34)=0,"",34&" "&INDEX(Klassenliste!$C$6:$C$40,34)&" "&LEFT(INDEX(Klassenliste!$B$6:$B$40,34),1)&".")
AA39: =IF(INDEX(Klassenliste!$B$6:$B$40,35)=0,"",35&" "&INDEX(Klassenliste!$C$6:$C$40,35)&" "&LEFT(INDEX(Klassenliste!$B$6:$B$40,35),1)&".")

Sheet Anw 1.HJ
A1: Anwesenheit 1. Halbjahr | AI1: =HYPERLINK("#Start!A1","⌂")
B2: e = entschuldigt · u = unentschuldigt · leer = anwesend (eine Spalte je Termin/Stunde)
E4: Datum →
A5: Nr | B5: Name | C5: Vorname | D5: FS | E5: uE
A6: 1 | B6: =IF(INDEX(Klassenliste!$B$6:$B$40,1)=0,"",INDEX(Klassenliste!$B$6:$B$40,1)) | C6: =IF(INDEX(Klassenliste!$C$6:$C$40,1)=0,"",INDEX(Klassenliste!$C$6:$C$40,1)) | D6: =IF($B6="","",COUNTIF(F6:AI6,"e")+COUNTIF(F6:AI6,"u")) | E6: =IF($B6="","",COUNTIF(F6:AI6,"u"))
A7: 2 | B7: =IF(INDEX(Klassenliste!$B$6:$B$40,2)=0,"",INDEX(Klassenliste!$B$6:$B$40,2)) | C7: =IF(INDEX(Klassenliste!$C$6:$C$40,2)=0,"",INDEX(Klassenliste!$C$6:$C$40,2)) | D7: =IF($B7="","",COUNTIF(F7:AI7,"e")+COUNTIF(F7:AI7,"u")) | E7: =IF($B7="","",COUNTIF(F7:AI7,"u"))
A8: 3 | B8: =IF(INDEX(Klassenliste!$B$6:$B$40,3)=0,"",INDEX(Klassenliste!$B$6:$B$40,3)) | C8: =IF(INDEX(Klassenliste!$C$6:$C$40,3)=0,"",INDEX(Klassenliste!$C$6:$C$40,3)) | D8: =IF($B8="","",COUNTIF(F8:AI8,"e")+COUNTIF(F8:AI8,"u")) | E8: =IF($B8="","",COUNTIF(F8:AI8,"u"))
A9: 4 | B9: =IF(INDEX(Klassenliste!$B$6:$B$40,4)=0,"",INDEX(Klassenliste!$B$6:$B$40,4)) | C9: =IF(INDEX(Klassenliste!$C$6:$C$40,4)=0,"",INDEX(Klassenliste!$C$6:$C$40,4)) | D9: =IF($B9="","",COUNTIF(F9:AI9,"e")+COUNTIF(F9:AI9,"u")) | E9: =IF($B9="","",COUNTIF(F9:AI9,"u"))
A10: 5 | B10: =IF(INDEX(Klassenliste!$B$6:$B$40,5)=0,"",INDEX(Klassenliste!$B$6:$B$40,5)) | C10: =IF(INDEX(Klassenliste!$C$6:$C$40,5)=0,"",INDEX(Klassenliste!$C$6:$C$40,5)) | D10: =IF($B10="","",COUNTIF(F10:AI10,"e")+COUNTIF(F10:AI10,"u")) | E10: =IF($B10="","",COUNTIF(F10:AI10,"u"))
A11: 6 | B11: =IF(INDEX(Klassenliste!$B$6:$B$40,6)=0,"",INDEX(Klassenliste!$B$6:$B$40,6)) | C11: =IF(INDEX(Klassenliste!$C$6:$C$40,6)=0,"",INDEX(Klassenliste!$C$6:$C$40,6)) | D11: =IF($B11="","",COUNTIF(F11:AI11,"e")+COUNTIF(F11:AI11,"u")) | E11: =IF($B11="","",COUNTIF(F11:AI11,"u"))
A12: 7 | B12: =IF(INDEX(Klassenliste!$B$6:$B$40,7)=0,"",INDEX(Klassenliste!$B$6:$B$40,7)) | C12: =IF(INDEX(Klassenliste!$C$6:$C$40,7)=0,"",INDEX(Klassenliste!$C$6:$C$40,7)) | D12: =IF($B12="","",COUNTIF(F12:AI12,"e")+COUNTIF(F12:AI12,"u")) | E12: =IF($B12="","",COUNTIF(F12:AI12,"u"))
A13: 8 | B13: =IF(INDEX(Klassenliste!$B$6:$B$40,8)=0,"",INDEX(Klassenliste!$B$6:$B$40,8)) | C13: =IF(INDEX(Klassenliste!$C$6:$C$40,8)=0,"",INDEX(Klassenliste!$C$6:$C$40,8)) | D13: =IF($B13="","",COUNTIF(F13:AI13,"e")+COUNTIF(F13:AI13,"u")) | E13: =IF($B13="","",COUNTIF(F13:AI13,"u"))
A14: 9 | B14: =IF(INDEX(Klassenliste!$B$6:$B$40,9)=0,"",INDEX(Klassenliste!$B$6:$B$40,9)) | C14: =IF(INDEX(Klassenliste!$C$6:$C$40,9)=0,"",INDEX(Klassenliste!$C$6:$C$40,9)) | D14: =IF($B14="","",COUNTIF(F14:AI14,"e")+COUNTIF(F14:AI14,"u")) | E14: =IF($B14="","",COUNTIF(F14:AI14,"u"))
A15: 10 | B15: =IF(INDEX(Klassenliste!$B$6:$B$40,10)=0,"",INDEX(Klassenliste!$B$6:$B$40,10)) | C15: =IF(INDEX(Klassenliste!$C$6:$C$40,10)=0,"",INDEX(Klassenliste!$C$6:$C$40,10)) | D15: =IF($B15="","",COUNTIF(F15:AI15,"e")+COUNTIF(F15:AI15,"u")) | E15: =IF($B15="","",COUNTIF(F15:AI15,"u"))
A16: 11 | B16: =IF(INDEX(Klassenliste!$B$6:$B$40,11)=0,"",INDEX(Klassenliste!$B$6:$B$40,11)) | C16: =IF(INDEX(Klassenliste!$C$6:$C$40,11)=0,"",INDEX(Klassenliste!$C$6:$C$40,11)) | D16: =IF($B16="","",COUNTIF(F16:AI16,"e")+COUNTIF(F16:AI16,"u")) | E16: =IF($B16="","",COUNTIF(F16:AI16,"u"))
A17: 12 | B17: =IF(INDEX(Klassenliste!$B$6:$B$40,12)=0,"",INDEX(Klassenliste!$B$6:$B$40,12)) | C17: =IF(INDEX(Klassenliste!$C$6:$C$40,12)=0,"",INDEX(Klassenliste!$C$6:$C$40,12)) | D17: =IF($B17="","",COUNTIF(F17:AI17,"e")+COUNTIF(F17:AI17,"u")) | E17: =IF($B17="","",COUNTIF(F17:AI17,"u"))
A18: 13 | B18: =IF(INDEX(Klassenliste!$B$6:$B$40,13)=0,"",INDEX(Klassenliste!$B$6:$B$40,13)) | C18: =IF(INDEX(Klassenliste!$C$6:$C$40,13)=0,"",INDEX(Klassenliste!$C$6:$C$40,13)) | D18: =IF($B18="","",COUNTIF(F18:AI18,"e")+COUNTIF(F18:AI18,"u")) | E18: =IF($B18="","",COUNTIF(F18:AI18,"u"))
A19: 14 | B19: =IF(INDEX(Klassenliste!$B$6:$B$40,14)=0,"",INDEX(Klassenliste!$B$6:$B$40,14)) | C19: =IF(INDEX(Klassenliste!$C$6:$C$40,14)=0,"",INDEX(Klassenliste!$C$6:$C$40,14)) | D19: =IF($B19="","",COUNTIF(F19:AI19,"e")+COUNTIF(F19:AI19,"u")) | E19: =IF($B19="","",COUNTIF(F19:AI19,"u"))
A20: 15 | B20: =IF(INDEX(Klassenliste!$B$6:$B$40,15)=0,"",INDEX(Klassenliste!$B$6:$B$40,15)) | C20: =IF(INDEX(Klassenliste!$C$6:$C$40,15)=0,"",INDEX(Klassenliste!$C$6:$C$40,15)) | D20: =IF($B20="","",COUNTIF(F20:AI20,"e")+COUNTIF(F20:AI20,"u")) | E20: =IF($B20="","",COUNTIF(F20:AI20,"u"))
A21: 16 | B21: =IF(INDEX(Klassenliste!$B$6:$B$40,16)=0,"",INDEX(Klassenliste!$B$6:$B$40,16)) | C21: =IF(INDEX(Klassenliste!$C$6:$C$40,16)=0,"",INDEX(Klassenliste!$C$6:$C$40,16)) | D21: =IF($B21="","",COUNTIF(F21:AI21,"e")+COUNTIF(F21:AI21,"u")) | E21: =IF($B21="","",COUNTIF(F21:AI21,"u"))
A22: 17 | B22: =IF(INDEX(Klassenliste!$B$6:$B$40,17)=0,"",INDEX(Klassenliste!$B$6:$B$40,17)) | C22: =IF(INDEX(Klassenliste!$C$6:$C$40,17)=0,"",INDEX(Klassenliste!$C$6:$C$40,17)) | D22: =IF($B22="","",COUNTIF(F22:AI22,"e")+COUNTIF(F22:AI22,"u")) | E22: =IF($B22="","",COUNTIF(F22:AI22,"u"))
A23: 18 | B23: =IF(INDEX(Klassenliste!$B$6:$B$40,18)=0,"",INDEX(Klassenliste!$B$6:$B$40,18)) | C23: =IF(INDEX(Klassenliste!$C$6:$C$40,18)=0,"",INDEX(Klassenliste!$C$6:$C$40,18)) | D23: =IF($B23="","",COUNTIF(F23:AI23,"e")+COUNTIF(F23:AI23,"u")) | E23: =IF($B23="","",COUNTIF(F23:AI23,"u"))
A24: 19 | B24: =IF(INDEX(Klassenliste!$B$6:$B$40,19)=0,"",INDEX(Klassenliste!$B$6:$B$40,19)) | C24: =IF(INDEX(Klassenliste!$C$6:$C$40,19)=0,"",INDEX(Klassenliste!$C$6:$C$40,19)) | D24: =IF($B24="","",COUNTIF(F24:AI24,"e")+COUNTIF(F24:AI24,"u")) | E24: =IF($B24="","",COUNTIF(F24:AI24,"u"))
A25: 20 | B25: =IF(INDEX(Klassenliste!$B$6:$B$40,20)=0,"",INDEX(Klassenliste!$B$6:$B$40,20)) | C25: =IF(INDEX(Klassenliste!$C$6:$C$40,20)=0,"",INDEX(Klassenliste!$C$6:$C$40,20)) | D25: =IF($B25="","",COUNTIF(F25:AI25,"e")+COUNTIF(F25:AI25,"u")) | E25: =IF($B25="","",COUNTIF(F25:AI25,"u"))
A26: 21 | B26: =IF(INDEX(Klassenliste!$B$6:$B$40,21)=0,"",INDEX(Klassenliste!$B$6:$B$40,21)) | C26: =IF(INDEX(Klassenliste!$C$6:$C$40,21)=0,"",INDEX(Klassenliste!$C$6:$C$40,21)) | D26: =IF($B26="","",COUNTIF(F26:AI26,"e")+COUNTIF(F26:AI26,"u")) | E26: =IF($B26="","",COUNTIF(F26:AI26,"u"))
A27: 22 | B27: =IF(INDEX(Klassenliste!$B$6:$B$40,22)=0,"",INDEX(Klassenliste!$B$6:$B$40,22)) | C27: =IF(INDEX(Klassenliste!$C$6:$C$40,22)=0,"",INDEX(Klassenliste!$C$6:$C$40,22)) | D27: =IF($B27="","",COUNTIF(F27:AI27,"e")+COUNTIF(F27:AI27,"u")) | E27: =IF($B27="","",COUNTIF(F27:AI27,"u"))
A28: 23 | B28: =IF(INDEX(Klassenliste!$B$6:$B$40,23)=0,"",INDEX(Klassenliste!$B$6:$B$40,23)) | C28: =IF(INDEX(Klassenliste!$C$6:$C$40,23)=0,"",INDEX(Klassenliste!$C$6:$C$40,23)) | D28: =IF($B28="","",COUNTIF(F28:AI28,"e")+COUNTIF(F28:AI28,"u")) | E28: =IF($B28="","",COUNTIF(F28:AI28,"u"))
A29: 24 | B29: =IF(INDEX(Klassenliste!$B$6:$B$40,24)=0,"",INDEX(Klassenliste!$B$6:$B$40,24)) | C29: =IF(INDEX(Klassenliste!$C$6:$C$40,24)=0,"",INDEX(Klassenliste!$C$6:$C$40,24)) | D29: =IF($B29="","",COUNTIF(F29:AI29,"e")+COUNTIF(F29:AI29,"u")) | E29: =IF($B29="","",COUNTIF(F29:AI29,"u"))
A30: 25 | B30: =IF(INDEX(Klassenliste!$B$6:$B$40,25)=0,"",INDEX(Klassenliste!$B$6:$B$40,25)) | C30: =IF(INDEX(Klassenliste!$C$6:$C$40,25)=0,"",INDEX(Klassenliste!$C$6:$C$40,25)) | D30: =IF($B30="","",COUNTIF(F30:AI30,"e")+COUNTIF(F30:AI30,"u")) | E30: =IF($B30="","",COUNTIF(F30:AI30,"u"))
A31: 26 | B31: =IF(INDEX(Klassenliste!$B$6:$B$40,26)=0,"",INDEX(Klassenliste!$B$6:$B$40,26)) | C31: =IF(INDEX(Klassenliste!$C$6:$C$40,26)=0,"",INDEX(Klassenliste!$C$6:$C$40,26)) | D31: =IF($B31="","",COUNTIF(F31:AI31,"e")+COUNTIF(F31:AI31,"u")) | E31: =IF($B31="","",COUNTIF(F31:AI31,"u"))
A32: 27 | B32: =IF(INDEX(Klassenliste!$B$6:$B$40,27)=0,"",INDEX(Klassenliste!$B$6:$B$40,27)) | C32: =IF(INDEX(Klassenliste!$C$6:$C$40,27)=0,"",INDEX(Klassenliste!$C$6:$C$40,27)) | D32: =IF($B32="","",COUNTIF(F32:AI32,"e")+COUNTIF(F32:AI32,"u")) | E32: =IF($B32="","",COUNTIF(F32:AI32,"u"))
A33: 28 | B33: =IF(INDEX(Klassenliste!$B$6:$B$40,28)=0,"",INDEX(Klassenliste!$B$6:$B$40,28)) | C33: =IF(INDEX(Klassenliste!$C$6:$C$40,28)=0,"",INDEX(Klassenliste!$C$6:$C$40,28)) | D33: =IF($B33="","",COUNTIF(F33:AI33,"e")+COUNTIF(F33:AI33,"u")) | E33: =IF($B33="","",COUNTIF(F33:AI33,"u"))
A34: 29 | B34: =IF(INDEX(Klassenliste!$B$6:$B$40,29)=0,"",INDEX(Klassenliste!$B$6:$B$40,29)) | C34: =IF(INDEX(Klassenliste!$C$6:$C$40,29)=0,"",INDEX(Klassenliste!$C$6:$C$40,29)) | D34: =IF($B34="","",COUNTIF(F34:AI34,"e")+COUNTIF(F34:AI34,"u")) | E34: =IF($B34="","",COUNTIF(F34:AI34,"u"))
A35: 30 | B35: =IF(INDEX(Klassenliste!$B$6:$B$40,30)=0,"",INDEX(Klassenliste!$B$6:$B$40,30)) | C35: =IF(INDEX(Klassenliste!$C$6:$C$40,30)=0,"",INDEX(Klassenliste!$C$6:$C$40,30)) | D35: =IF($B35="","",COUNTIF(F35:AI35,"e")+COUNTIF(F35:AI35,"u")) | E35: =IF($B35="","",COUNTIF(F35:AI35,"u"))
A36: 31 | B36: =IF(INDEX(Klassenliste!$B$6:$B$40,31)=0,"",INDEX(Klassenliste!$B$6:$B$40,31)) | C36: =IF(INDEX(Klassenliste!$C$6:$C$40,31)=0,"",INDEX(Klassenliste!$C$6:$C$40,31)) | D36: =IF($B36="","",COUNTIF(F36:AI36,"e")+COUNTIF(F36:AI36,"u")) | E36: =IF($B36="","",COUNTIF(F36:AI36,"u"))
A37: 32 | B37: =IF(INDEX(Klassenliste!$B$6:$B$40,32)=0,"",INDEX(Klassenliste!$B$6:$B$40,32)) | C37: =IF(INDEX(Klassenliste!$C$6:$C$40,32)=0,"",INDEX(Klassenliste!$C$6:$C$40,32)) | D37: =IF($B37="","",COUNTIF(F37:AI37,"e")+COUNTIF(F37:AI37,"u")) | E37: =IF($B37="","",COUNTIF(F37:AI37,"u"))
A38: 33 | B38: =IF(INDEX(Klassenliste!$B$6:$B$40,33)=0,"",INDEX(Klassenliste!$B$6:$B$40,33)) | C38: =IF(INDEX(Klassenliste!$C$6:$C$40,33)=0,"",INDEX(Klassenliste!$C$6:$C$40,33)) | D38: =IF($B38="","",COUNTIF(F38:AI38,"e")+COUNTIF(F38:AI38,"u")) | E38: =IF($B38="","",COUNTIF(F38:AI38,"u"))
A39: 34 | B39: =IF(INDEX(Klassenliste!$B$6:$B$40,34)=0,"",INDEX(Klassenliste!$B$6:$B$40,34)) | C39: =IF(INDEX(Klassenliste!$C$6:$C$40,34)=0,"",INDEX(Klassenliste!$C$6:$C$40,34)) | D39: =IF($B39="","",COUNTIF(F39:AI39,"e")+COUNTIF(F39:AI39,"u")) | E39: =IF($B39="","",COUNTIF(F39:AI39,"u"))
A40: 35 | B40: =IF(INDEX(Klassenliste!$B$6:$B$40,35)=0,"",INDEX(Klassenliste!$B$6:$B$40,35)) | C40: =IF(INDEX(Klassenliste!$C$6:$C$40,35)=0,"",INDEX(Klassenliste!$C$6:$C$40,35)) | D40: =IF($B40="","",COUNTIF(F40:AI40,"e")+COUNTIF(F40:AI40,"u")) | E40: =IF($B40="","",COUNTIF(F40:AI40,"u"))

Sheet Mat 1.HJ
A1: Material & Lernzeit 1. Halbjahr | AJ1: =HYPERLINK("#Start!A1","⌂")
B2: M = Material vergessen · L = Lernzeit/HA fehlt · i = iPad fehlt/ungeladen — kombinierbar (z. B. MLi) · mehrere Schüler: Zellen markieren, Kürzel tippen, Strg+Enter
F4: Datum →
A5: Nr | B5: Name | C5: Vorname | D5: M | E5: L | F5: iP
A6: 1 | B6: =IF(INDEX(Klassenliste!$B$6:$B$40,1)=0,"",INDEX(Klassenliste!$B$6:$B$40,1)) | C6: =IF(INDEX(Klassenliste!$C$6:$C$40,1)=0,"",INDEX(Klassenliste!$C$6:$C$40,1)) | D6: =IF($B6="","",COUNTIF(G6:AJ6,"*M*")) | E6: =IF($B6="","",COUNTIF(G6:AJ6,"*L*")) | F6: =IF($B6="","",COUNTIF(G6:AJ6,"*i*"))
A7: 2 | B7: =IF(INDEX(Klassenliste!$B$6:$B$40,2)=0,"",INDEX(Klassenliste!$B$6:$B$40,2)) | C7: =IF(INDEX(Klassenliste!$C$6:$C$40,2)=0,"",INDEX(Klassenliste!$C$6:$C$40,2)) | D7: =IF($B7="","",COUNTIF(G7:AJ7,"*M*")) | E7: =IF($B7="","",COUNTIF(G7:AJ7,"*L*")) | F7: =IF($B7="","",COUNTIF(G7:AJ7,"*i*"))
A8: 3 | B8: =IF(INDEX(Klassenliste!$B$6:$B$40,3)=0,"",INDEX(Klassenliste!$B$6:$B$40,3)) | C8: =IF(INDEX(Klassenliste!$C$6:$C$40,3)=0,"",INDEX(Klassenliste!$C$6:$C$40,3)) | D8: =IF($B8="","",COUNTIF(G8:AJ8,"*M*")) | E8: =IF($B8="","",COUNTIF(G8:AJ8,"*L*")) | F8: =IF($B8="","",COUNTIF(G8:AJ8,"*i*"))
A9: 4 | B9: =IF(INDEX(Klassenliste!$B$6:$B$40,4)=0,"",INDEX(Klassenliste!$B$6:$B$40,4)) | C9: =IF(INDEX(Klassenliste!$C$6:$C$40,4)=0,"",INDEX(Klassenliste!$C$6:$C$40,4)) | D9: =IF($B9="","",COUNTIF(G9:AJ9,"*M*")) | E9: =IF($B9="","",COUNTIF(G9:AJ9,"*L*")) | F9: =IF($B9="","",COUNTIF(G9:AJ9,"*i*"))
A10: 5 | B10: =IF(INDEX(Klassenliste!$B$6:$B$40,5)=0,"",INDEX(Klassenliste!$B$6:$B$40,5)) | C10: =IF(INDEX(Klassenliste!$C$6:$C$40,5)=0,"",INDEX(Klassenliste!$C$6:$C$40,5)) | D10: =IF($B10="","",COUNTIF(G10:AJ10,"*M*")) | E10: =IF($B10="","",COUNTIF(G10:AJ10,"*L*")) | F10: =IF($B10="","",COUNTIF(G10:AJ10,"*i*"))
A11: 6 | B11: =IF(INDEX(Klassenliste!$B$6:$B$40,6)=0,"",INDEX(Klassenliste!$B$6:$B$40,6)) | C11: =IF(INDEX(Klassenliste!$C$6:$C$40,6)=0,"",INDEX(Klassenliste!$C$6:$C$40,6)) | D11: =IF($B11="","",COUNTIF(G11:AJ11,"*M*")) | E11: =IF($B11="","",COUNTIF(G11:AJ11,"*L*")) | F11: =IF($B11="","",COUNTIF(G11:AJ11,"*i*"))
A12: 7 | B12: =IF(INDEX(Klassenliste!$B$6:$B$40,7)=0,"",INDEX(Klassenliste!$B$6:$B$40,7)) | C12: =IF(INDEX(Klassenliste!$C$6:$C$40,7)=0,"",INDEX(Klassenliste!$C$6:$C$40,7)) | D12: =IF($B12="","",COUNTIF(G12:AJ12,"*M*")) | E12: =IF($B12="","",COUNTIF(G12:AJ12,"*L*")) | F12: =IF($B12="","",COUNTIF(G12:AJ12,"*i*"))
A13: 8 | B13: =IF(INDEX(Klassenliste!$B$6:$B$40,8)=0,"",INDEX(Klassenliste!$B$6:$B$40,8)) | C13: =IF(INDEX(Klassenliste!$C$6:$C$40,8)=0,"",INDEX(Klassenliste!$C$6:$C$40,8)) | D13: =IF($B13="","",COUNTIF(G13:AJ13,"*M*")) | E13: =IF($B13="","",COUNTIF(G13:AJ13,"*L*")) | F13: =IF($B13="","",COUNTIF(G13:AJ13,"*i*"))
A14: 9 | B14: =IF(INDEX(Klassenliste!$B$6:$B$40,9)=0,"",INDEX(Klassenliste!$B$6:$B$40,9)) | C14: =IF(INDEX(Klassenliste!$C$6:$C$40,9)=0,"",INDEX(Klassenliste!$C$6:$C$40,9)) | D14: =IF($B14="","",COUNTIF(G14:AJ14,"*M*")) | E14: =IF($B14="","",COUNTIF(G14:AJ14,"*L*")) | F14: =IF($B14="","",COUNTIF(G14:AJ14,"*i*"))
A15: 10 | B15: =IF(INDEX(Klassenliste!$B$6:$B$40,10)=0,"",INDEX(Klassenliste!$B$6:$B$40,10)) | C15: =IF(INDEX(Klassenliste!$C$6:$C$40,10)=0,"",INDEX(Klassenliste!$C$6:$C$40,10)) | D15: =IF($B15="","",COUNTIF(G15:AJ15,"*M*")) | E15: =IF($B15="","",COUNTIF(G15:AJ15,"*L*")) | F15: =IF($B15="","",COUNTIF(G15:AJ15,"*i*"))
A16: 11 | B16: =IF(INDEX(Klassenliste!$B$6:$B$40,11)=0,"",INDEX(Klassenliste!$B$6:$B$40,11)) | C16: =IF(INDEX(Klassenliste!$C$6:$C$40,11)=0,"",INDEX(Klassenliste!$C$6:$C$40,11)) | D16: =IF($B16="","",COUNTIF(G16:AJ16,"*M*")) | E16: =IF($B16="","",COUNTIF(G16:AJ16,"*L*")) | F16: =IF($B16="","",COUNTIF(G16:AJ16,"*i*"))
A17: 12 | B17: =IF(INDEX(Klassenliste!$B$6:$B$40,12)=0,"",INDEX(Klassenliste!$B$6:$B$40,12)) | C17: =IF(INDEX(Klassenliste!$C$6:$C$40,12)=0,"",INDEX(Klassenliste!$C$6:$C$40,12)) | D17: =IF($B17="","",COUNTIF(G17:AJ17,"*M*")) | E17: =IF($B17="","",COUNTIF(G17:AJ17,"*L*")) | F17: =IF($B17="","",COUNTIF(G17:AJ17,"*i*"))
A18: 13 | B18: =IF(INDEX(Klassenliste!$B$6:$B$40,13)=0,"",INDEX(Klassenliste!$B$6:$B$40,13)) | C18: =IF(INDEX(Klassenliste!$C$6:$C$40,13)=0,"",INDEX(Klassenliste!$C$6:$C$40,13)) | D18: =IF($B18="","",COUNTIF(G18:AJ18,"*M*")) | E18: =IF($B18="","",COUNTIF(G18:AJ18,"*L*")) | F18: =IF($B18="","",COUNTIF(G18:AJ18,"*i*"))
A19: 14 | B19: =IF(INDEX(Klassenliste!$B$6:$B$40,14)=0,"",INDEX(Klassenliste!$B$6:$B$40,14)) | C19: =IF(INDEX(Klassenliste!$C$6:$C$40,14)=0,"",INDEX(Klassenliste!$C$6:$C$40,14)) | D19: =IF($B19="","",COUNTIF(G19:AJ19,"*M*")) | E19: =IF($B19="","",COUNTIF(G19:AJ19,"*L*")) | F19: =IF($B19="","",COUNTIF(G19:AJ19,"*i*"))
A20: 15 | B20: =IF(INDEX(Klassenliste!$B$6:$B$40,15)=0,"",INDEX(Klassenliste!$B$6:$B$40,15)) | C20: =IF(INDEX(Klassenliste!$C$6:$C$40,15)=0,"",INDEX(Klassenliste!$C$6:$C$40,15)) | D20: =IF($B20="","",COUNTIF(G20:AJ20,"*M*")) | E20: =IF($B20="","",COUNTIF(G20:AJ20,"*L*")) | F20: =IF($B20="","",COUNTIF(G20:AJ20,"*i*"))
A21: 16 | B21: =IF(INDEX(Klassenliste!$B$6:$B$40,16)=0,"",INDEX(Klassenliste!$B$6:$B$40,16)) | C21: =IF(INDEX(Klassenliste!$C$6:$C$40,16)=0,"",INDEX(Klassenliste!$C$6:$C$40,16)) | D21: =IF($B21="","",COUNTIF(G21:AJ21,"*M*")) | E21: =IF($B21="","",COUNTIF(G21:AJ21,"*L*")) | F21: =IF($B21="","",COUNTIF(G21:AJ21,"*i*"))
A22: 17 | B22: =IF(INDEX(Klassenliste!$B$6:$B$40,17)=0,"",INDEX(Klassenliste!$B$6:$B$40,17)) | C22: =IF(INDEX(Klassenliste!$C$6:$C$40,17)=0,"",INDEX(Klassenliste!$C$6:$C$40,17)) | D22: =IF($B22="","",COUNTIF(G22:AJ22,"*M*")) | E22: =IF($B22="","",COUNTIF(G22:AJ22,"*L*")) | F22: =IF($B22="","",COUNTIF(G22:AJ22,"*i*"))
A23: 18 | B23: =IF(INDEX(Klassenliste!$B$6:$B$40,18)=0,"",INDEX(Klassenliste!$B$6:$B$40,18)) | C23: =IF(INDEX(Klassenliste!$C$6:$C$40,18)=0,"",INDEX(Klassenliste!$C$6:$C$40,18)) | D23: =IF($B23="","",COUNTIF(G23:AJ23,"*M*")) | E23: =IF($B23="","",COUNTIF(G23:AJ23,"*L*")) | F23: =IF($B23="","",COUNTIF(G23:AJ23,"*i*"))
A24: 19 | B24: =IF(INDEX(Klassenliste!$B$6:$B$40,19)=0,"",INDEX(Klassenliste!$B$6:$B$40,19)) | C24: =IF(INDEX(Klassenliste!$C$6:$C$40,19)=0,"",INDEX(Klassenliste!$C$6:$C$40,19)) | D24: =IF($B24="","",COUNTIF(G24:AJ24,"*M*")) | E24: =IF($B24="","",COUNTIF(G24:AJ24,"*L*")) | F24: =IF($B24="","",COUNTIF(G24:AJ24,"*i*"))
A25: 20 | B25: =IF(INDEX(Klassenliste!$B$6:$B$40,20)=0,"",INDEX(Klassenliste!$B$6:$B$40,20)) | C25: =IF(INDEX(Klassenliste!$C$6:$C$40,20)=0,"",INDEX(Klassenliste!$C$6:$C$40,20)) | D25: =IF($B25="","",COUNTIF(G25:AJ25,"*M*")) | E25: =IF($B25="","",COUNTIF(G25:AJ25,"*L*")) | F25: =IF($B25="","",COUNTIF(G25:AJ25,"*i*"))
A26: 21 | B26: =IF(INDEX(Klassenliste!$B$6:$B$40,21)=0,"",INDEX(Klassenliste!$B$6:$B$40,21)) | C26: =IF(INDEX(Klassenliste!$C$6:$C$40,21)=0,"",INDEX(Klassenliste!$C$6:$C$40,21)) | D26: =IF($B26="","",COUNTIF(G26:AJ26,"*M*")) | E26: =IF($B26="","",COUNTIF(G26:AJ26,"*L*")) | F26: =IF($B26="","",COUNTIF(G26:AJ26,"*i*"))
A27: 22 | B27: =IF(INDEX(Klassenliste!$B$6:$B$40,22)=0,"",INDEX(Klassenliste!$B$6:$B$40,22)) | C27: =IF(INDEX(Klassenliste!$C$6:$C$40,22)=0,"",INDEX(Klassenliste!$C$6:$C$40,22)) | D27: =IF($B27="","",COUNTIF(G27:AJ27,"*M*")) | E27: =IF($B27="","",COUNTIF(G27:AJ27,"*L*")) | F27: =IF($B27="","",COUNTIF(G27:AJ27,"*i*"))
A28: 23 | B28: =IF(INDEX(Klassenliste!$B$6:$B$40,23)=0,"",INDEX(Klassenliste!$B$6:$B$40,23)) | C28: =IF(INDEX(Klassenliste!$C$6:$C$40,23)=0,"",INDEX(Klassenliste!$C$6:$C$40,23)) | D28: =IF($B28="","",COUNTIF(G28:AJ28,"*M*")) | E28: =IF($B28="","",COUNTIF(G28:AJ28,"*L*")) | F28: =IF($B28="","",COUNTIF(G28:AJ28,"*i*"))
A29: 24 | B29: =IF(INDEX(Klassenliste!$B$6:$B$40,24)=0,"",INDEX(Klassenliste!$B$6:$B$40,24)) | C29: =IF(INDEX(Klassenliste!$C$6:$C$40,24)=0,"",INDEX(Klassenliste!$C$6:$C$40,24)) | D29: =IF($B29="","",COUNTIF(G29:AJ29,"*M*")) | E29: =IF($B29="","",COUNTIF(G29:AJ29,"*L*")) | F29: =IF($B29="","",COUNTIF(G29:AJ29,"*i*"))
A30: 25 | B30: =IF(INDEX(Klassenliste!$B$6:$B$40,25)=0,"",INDEX(Klassenliste!$B$6:$B$40,25)) | C30: =IF(INDEX(Klassenliste!$C$6:$C$40,25)=0,"",INDEX(Klassenliste!$C$6:$C$40,25)) | D30: =IF($B30="","",COUNTIF(G30:AJ30,"*M*")) | E30: =IF($B30="","",COUNTIF(G30:AJ30,"*L*")) | F30: =IF($B30="","",COUNTIF(G30:AJ30,"*i*"))
A31: 26 | B31: =IF(INDEX(Klassenliste!$B$6:$B$40,26)=0,"",INDEX(Klassenliste!$B$6:$B$40,26)) | C31: =IF(INDEX(Klassenliste!$C$6:$C$40,26)=0,"",INDEX(Klassenliste!$C$6:$C$40,26)) | D31: =IF($B31="","",COUNTIF(G31:AJ31,"*M*")) | E31: =IF($B31="","",COUNTIF(G31:AJ31,"*L*")) | F31: =IF($B31="","",COUNTIF(G31:AJ31,"*i*"))
A32: 27 | B32: =IF(INDEX(Klassenliste!$B$6:$B$40,27)=0,"",INDEX(Klassenliste!$B$6:$B$40,27)) | C32: =IF(INDEX(Klassenliste!$C$6:$C$40,27)=0,"",INDEX(Klassenliste!$C$6:$C$40,27)) | D32: =IF($B32="","",COUNTIF(G32:AJ32,"*M*")) | E32: =IF($B32="","",COUNTIF(G32:AJ32,"*L*")) | F32: =IF($B32="","",COUNTIF(G32:AJ32,"*i*"))
A33: 28 | B33: =IF(INDEX(Klassenliste!$B$6:$B$40,28)=0,"",INDEX(Klassenliste!$B$6:$B$40,28)) | C33: =IF(INDEX(Klassenliste!$C$6:$C$40,28)=0,"",INDEX(Klassenliste!$C$6:$C$40,28)) | D33: =IF($B33="","",COUNTIF(G33:AJ33,"*M*")) | E33: =IF($B33="","",COUNTIF(G33:AJ33,"*L*")) | F33: =IF($B33="","",COUNTIF(G33:AJ33,"*i*"))
A34: 29 | B34: =IF(INDEX(Klassenliste!$B$6:$B$40,29)=0,"",INDEX(Klassenliste!$B$6:$B$40,29)) | C34: =IF(INDEX(Klassenliste!$C$6:$C$40,29)=0,"",INDEX(Klassenliste!$C$6:$C$40,29)) | D34: =IF($B34="","",COUNTIF(G34:AJ34,"*M*")) | E34: =IF($B34="","",COUNTIF(G34:AJ34,"*L*")) | F34: =IF($B34="","",COUNTIF(G34:AJ34,"*i*"))
A35: 30 | B35: =IF(INDEX(Klassenliste!$B$6:$B$40,30)=0,"",INDEX(Klassenliste!$B$6:$B$40,30)) | C35: =IF(INDEX(Klassenliste!$C$6:$C$40,30)=0,"",INDEX(Klassenliste!$C$6:$C$40,30)) | D35: =IF($B35="","",COUNTIF(G35:AJ35,"*M*")) | E35: =IF($B35="","",COUNTIF(G35:AJ35,"*L*")) | F35: =IF($B35="","",COUNTIF(G35:AJ35,"*i*"))
A36: 31 | B36: =IF(INDEX(Klassenliste!$B$6:$B$40,31)=0,"",INDEX(Klassenliste!$B$6:$B$40,31)) | C36: =IF(INDEX(Klassenliste!$C$6:$C$40,31)=0,"",INDEX(Klassenliste!$C$6:$C$40,31)) | D36: =IF($B36="","",COUNTIF(G36:AJ36,"*M*")) | E36: =IF($B36="","",COUNTIF(G36:AJ36,"*L*")) | F36: =IF($B36="","",COUNTIF(G36:AJ36,"*i*"))
A37: 32 | B37: =IF(INDEX(Klassenliste!$B$6:$B$40,32)=0,"",INDEX(Klassenliste!$B$6:$B$40,32)) | C37: =IF(INDEX(Klassenliste!$C$6:$C$40,32)=0,"",INDEX(Klassenliste!$C$6:$C$40,32)) | D37: =IF($B37="","",COUNTIF(G37:AJ37,"*M*")) | E37: =IF($B37="","",COUNTIF(G37:AJ37,"*L*")) | F37: =IF($B37="","",COUNTIF(G37:AJ37,"*i*"))
A38: 33 | B38: =IF(INDEX(Klassenliste!$B$6:$B$40,33)=0,"",INDEX(Klassenliste!$B$6:$B$40,33)) | C38: =IF(INDEX(Klassenliste!$C$6:$C$40,33)=0,"",INDEX(Klassenliste!$C$6:$C$40,33)) | D38: =IF($B38="","",COUNTIF(G38:AJ38,"*M*")) | E38: =IF($B38="","",COUNTIF(G38:AJ38,"*L*")) | F38: =IF($B38="","",COUNTIF(G38:AJ38,"*i*"))
A39: 34 | B39: =IF(INDEX(Klassenliste!$B$6:$B$40,34)=0,"",INDEX(Klassenliste!$B$6:$B$40,34)) | C39: =IF(INDEX(Klassenliste!$C$6:$C$40,34)=0,"",INDEX(Klassenliste!$C$6:$C$40,34)) | D39: =IF($B39="","",COUNTIF(G39:AJ39,"*M*")) | E39: =IF($B39="","",COUNTIF(G39:AJ39,"*L*")) | F39: =IF($B39="","",COUNTIF(G39:AJ39,"*i*"))
A40: 35 | B40: =IF(INDEX(Klassenliste!$B$6:$B$40,35)=0,"",INDEX(Klassenliste!$B$6:$B$40,35)) | C40: =IF(INDEX(Klassenliste!$C$6:$C$40,35)=0,"",INDEX(Klassenliste!$C$6:$C$40,35)) | D40: =IF($B40="","",COUNTIF(G40:AJ40,"*M*")) | E40: =IF($B40="","",COUNTIF(G40:AJ40,"*L*")) | F40: =IF($B40="","",COUNTIF(G40:AJ40,"*i*"))

Sheet Noten 1.HJ
A1: Notenübersicht 1. Halbjahr | AB1: =HYPERLINK("#Start!A1","⌂")
A2: =Klassenliste!$E$2&" · "&Klassenliste!$J$2&" · "&Klassenliste!$H$2&"" | L2: Einheit: Notenpunkte (0–15) · leere Zellen zählen nicht · Zeile 5 über m1–m6: frei beschriften (SoMi, Referat, Kurztest …)
D3: Quartalsnoten | F3: Quartal 1 · S = schriftlich (KA) · MA = Mitarbeit | P3: Quartal 2 | Z3: Halbjahr
C4: Gewichtung: | D4: 1 | E4: 1 | F4: 1 | G4: 1 | H4: 1 | I4: 1 | J4: 1 | K4: 1 | L4: 1 | M4: 1 | N4: 1 | O4: 1 | P4: 1 | Q4: 1 | R4: 1 | S4: 1 | T4: 1 | U4: 1 | V4: 1 | W4: 1 | X4: 1 | Y4: 1
C5: KA-Nr: | G5: 1 | I5: Art → | Q5: 2 | R5: 3 | S5: Art →
A6: Nr | B6: Name | C6: Vorname | D6: Q1 | E6: Q2 | F6: S (Q1) | G6: =IF(G$5="","(frei)","KA "&G$5) | H6: =IF(H$5="","(frei)","KA "&H$5) | I6: MA (Q1) | J6: m1 | K6: m2 | L6: m3 | M6: m4 | N6: m5 | O6: m6 | P6: S (Q2) | Q6: =IF(Q$5="","(frei)","KA "&Q$5) | R6: =IF(R$5="","(frei)","KA "&R$5) | S6: MA (Q2) | T6: m1 | U6: m2 | V6: m3 | W6: m4 | X6: m5 | Y6: m6 | Z6: HJ Ø | AA6: HJ Pkt | AB6: Note
A7: 1 | B7: =IF(INDEX(Klassenliste!$B$6:$B$40,1)=0,"",INDEX(Klassenliste!$B$6:$B$40,1)) | C7: =IF(INDEX(Klassenliste!$C$6:$C$40,1)=0,"",INDEX(Klassenliste!$C$6:$C$40,1)) | D7: =IF(((--ISNUMBER(F7))*$F$4+(--ISNUMBER(I7))*$I$4)=0,"",(IFERROR(F7*$F$4,0)+IFERROR(I7*$I$4,0))/((--ISNUMBER(F7))*$F$4+(--ISNUMBER(I7))*$I$4)) | E7: =IF(((--ISNUMBER(P7))*$P$4+(--ISNUMBER(S7))*$S$4)=0,"",(IFERROR(P7*$P$4,0)+IFERROR(S7*$S$4,0))/((--ISNUMBER(P7))*$P$4+(--ISNUMBER(S7))*$S$4)) | F7: =IF(SUMPRODUCT(--ISNUMBER(G7:H7),$G$4:$H$4)=0,"",SUMPRODUCT(G7:H7,$G$4:$H$4)/SUMPRODUCT(--ISNUMBER(G7:H7),$G$4:$H$4)) | G7: =IF(G$5="","",CHOOSE(G$5,KA1!$R8,KA2!$R8,KA3!$R8,KA4!$R8,KA5!$R8,KA6!$R8)) | H7: =IF(H$5="","",CHOOSE(H$5,KA1!$R8,KA2!$R8,KA3!$R8,KA4!$R8,KA5!$R8,KA6!$R8)) | I7: =IF(SUMPRODUCT(--ISNUMBER(J7:O7),$J$4:$O$4)=0,"",SUMPRODUCT(J7:O7,$J$4:$O$4)/SUMPRODUCT(--ISNUMBER(J7:O7),$J$4:$O$4)) | P7: =IF(SUMPRODUCT(--ISNUMBER(Q7:R7),$Q$4:$R$4)=0,"",SUMPRODUCT(Q7:R7,$Q$4:$R$4)/SUMPRODUCT(--ISNUMBER(Q7:R7),$Q$4:$R$4)) | Q7: =IF(Q$5="","",CHOOSE(Q$5,KA1!$R8,KA2!$R8,KA3!$R8,KA4!$R8,KA5!$R8,KA6!$R8)) | R7: =IF(R$5="","",CHOOSE(R$5,KA1!$R8,KA2!$R8,KA3!$R8,KA4!$R8,KA5!$R8,KA6!$R8)) | S7: =IF(SUMPRODUCT(--ISNUMBER(T7:Y7),$T$4:$Y$4)=0,"",SUMPRODUCT(T7:Y7,$T$4:$Y$4)/SUMPRODUCT(--ISNUMBER(T7:Y7),$T$4:$Y$4)) | Z7: =IF(((--ISNUMBER(D7))*$D$4+(--ISNUMBER(E7))*$E$4)=0,"",(IFERROR(D7*$D$4,0)+IFERROR(E7*$E$4,0))/((--ISNUMBER(D7))*$D$4+(--ISNUMBER(E7))*$E$4)) | AA7: =IF(Z7="","",ROUND(Z7,0)) | AB7: =IF(AA7="","",INDEX(Notentabelle!$B$4:$B$19,AA7+1))
A8: 2 | B8: =IF(INDEX(Klassenliste!$B$6:$B$40,2)=0,"",INDEX(Klassenliste!$B$6:$B$40,2)) | C8: =IF(INDEX(Klassenliste!$C$6:$C$40,2)=0,"",INDEX(Klassenliste!$C$6:$C$40,2)) | D8: =IF(((--ISNUMBER(F8))*$F$4+(--ISNUMBER(I8))*$I$4)=0,"",(IFERROR(F8*$F$4,0)+IFERROR(I8*$I$4,0))/((--ISNUMBER(F8))*$F$4+(--ISNUMBER(I8))*$I$4)) | E8: =IF(((--ISNUMBER(P8))*$P$4+(--ISNUMBER(S8))*$S$4)=0,"",(IFERROR(P8*$P$4,0)+IFERROR(S8*$S$4,0))/((--ISNUMBER(P8))*$P$4+(--ISNUMBER(S8))*$S$4)) | F8: =IF(SUMPRODUCT(--ISNUMBER(G8:H8),$G$4:$H$4)=0,"",SUMPRODUCT(G8:H8,$G$4:$H$4)/SUMPRODUCT(--ISNUMBER(G8:H8),$G$4:$H$4)) | G8: =IF(G$5="","",CHOOSE(G$5,KA1!$R9,KA2!$R9,KA3!$R9,KA4!$R9,KA5!$R9,KA6!$R9)) | H8: =IF(H$5="","",CHOOSE(H$5,KA1!$R9,KA2!$R9,KA3!$R9,KA4!$R9,KA5!$R9,KA6!$R9)) | I8: =IF(SUMPRODUCT(--ISNUMBER(J8:O8),$J$4:$O$4)=0,"",SUMPRODUCT(J8:O8,$J$4:$O$4)/SUMPRODUCT(--ISNUMBER(J8:O8),$J$4:$O$4)) | P8: =IF(SUMPRODUCT(--ISNUMBER(Q8:R8),$Q$4:$R$4)=0,"",SUMPRODUCT(Q8:R8,$Q$4:$R$4)/SUMPRODUCT(--ISNUMBER(Q8:R8),$Q$4:$R$4)) | Q8: =IF(Q$5="","",CHOOSE(Q$5,KA1!$R9,KA2!$R9,KA3!$R9,KA4!$R9,KA5!$R9,KA6!$R9)) | R8: =IF(R$5="","",CHOOSE(R$5,KA1!$R9,KA2!$R9,KA3!$R9,KA4!$R9,KA5!$R9,KA6!$R9)) | S8: =IF(SUMPRODUCT(--ISNUMBER(T8:Y8),$T$4:$Y$4)=0,"",SUMPRODUCT(T8:Y8,$T$4:$Y$4)/SUMPRODUCT(--ISNUMBER(T8:Y8),$T$4:$Y$4)) | Z8: =IF(((--ISNUMBER(D8))*$D$4+(--ISNUMBER(E8))*$E$4)=0,"",(IFERROR(D8*$D$4,0)+IFERROR(E8*$E$4,0))/((--ISNUMBER(D8))*$D$4+(--ISNUMBER(E8))*$E$4)) | AA8: =IF(Z8="","",ROUND(Z8,0)) | AB8: =IF(AA8="","",INDEX(Notentabelle!$B$4:$B$19,AA8+1))
A9: 3 | B9: =IF(INDEX(Klassenliste!$B$6:$B$40,3)=0,"",INDEX(Klassenliste!$B$6:$B$40,3)) | C9: =IF(INDEX(Klassenliste!$C$6:$C$40,3)=0,"",INDEX(Klassenliste!$C$6:$C$40,3)) | D9: =IF(((--ISNUMBER(F9))*$F$4+(--ISNUMBER(I9))*$I$4)=0,"",(IFERROR(F9*$F$4,0)+IFERROR(I9*$I$4,0))/((--ISNUMBER(F9))*$F$4+(--ISNUMBER(I9))*$I$4)) | E9: =IF(((--ISNUMBER(P9))*$P$4+(--ISNUMBER(S9))*$S$4)=0,"",(IFERROR(P9*$P$4,0)+IFERROR(S9*$S$4,0))/((--ISNUMBER(P9))*$P$4+(--ISNUMBER(S9))*$S$4)) | F9: =IF(SUMPRODUCT(--ISNUMBER(G9:H9),$G$4:$H$4)=0,"",SUMPRODUCT(G9:H9,$G$4:$H$4)/SUMPRODUCT(--ISNUMBER(G9:H9),$G$4:$H$4)) | G9: =IF(G$5="","",CHOOSE(G$5,KA1!$R10,KA2!$R10,KA3!$R10,KA4!$R10,KA5!$R10,KA6!$R10)) | H9: =IF(H$5="","",CHOOSE(H$5,KA1!$R10,KA2!$R10,KA3!$R10,KA4!$R10,KA5!$R10,KA6!$R10)) | I9: =IF(SUMPRODUCT(--ISNUMBER(J9:O9),$J$4:$O$4)=0,"",SUMPRODUCT(J9:O9,$J$4:$O$4)/SUMPRODUCT(--ISNUMBER(J9:O9),$J$4:$O$4)) | P9: =IF(SUMPRODUCT(--ISNUMBER(Q9:R9),$Q$4:$R$4)=0,"",SUMPRODUCT(Q9:R9,$Q$4:$R$4)/SUMPRODUCT(--ISNUMBER(Q9:R9),$Q$4:$R$4)) | Q9: =IF(Q$5="","",CHOOSE(Q$5,KA1!$R10,KA2!$R10,KA3!$R10,KA4!$R10,KA5!$R10,KA6!$R10)) | R9: =IF(R$5="","",CHOOSE(R$5,KA1!$R10,KA2!$R10,KA3!$R10,KA4!$R10,KA5!$R10,KA6!$R10)) | S9: =IF(SUMPRODUCT(--ISNUMBER(T9:Y9),$T$4:$Y$4)=0,"",SUMPRODUCT(T9:Y9,$T$4:$Y$4)/SUMPRODUCT(--ISNUMBER(T9:Y9),$T$4:$Y$4)) | Z9: =IF(((--ISNUMBER(D9))*$D$4+(--ISNUMBER(E9))*$E$4)=0,"",(IFERROR(D9*$D$4,0)+IFERROR(E9*$E$4,0))/((--ISNUMBER(D9))*$D$4+(--ISNUMBER(E9))*$E$4)) | AA9: =IF(Z9="","",ROUND(Z9,0)) | AB9: =IF(AA9="","",INDEX(Notentabelle!$B$4:$B$19,AA9+1))
A10: 4 | B10: =IF(INDEX(Klassenliste!$B$6:$B$40,4)=0,"",INDEX(Klassenliste!$B$6:$B$40,4)) | C10: =IF(INDEX(Klassenliste!$C$6:$C$40,4)=0,"",INDEX(Klassenliste!$C$6:$C$40,4)) | D10: =IF(((--ISNUMBER(F10))*$F$4+(--ISNUMBER(I10))*$I$4)=0,"",(IFERROR(F10*$F$4,0)+IFERROR(I10*$I$4,0))/((--ISNUMBER(F10))*$F$4+(--ISNUMBER(I10))*$I$4)) | E10: =IF(((--ISNUMBER(P10))*$P$4+(--ISNUMBER(S10))*$S$4)=0,"",(IFERROR(P10*$P$4,0)+IFERROR(S10*$S$4,0))/((--ISNUMBER(P10))*$P$4+(--ISNUMBER(S10))*$S$4)) | F10: =IF(SUMPRODUCT(--ISNUMBER(G10:H10),$G$4:$H$4)=0,"",SUMPRODUCT(G10:H10,$G$4:$H$4)/SUMPRODUCT(--ISNUMBER(G10:H10),$G$4:$H$4)) | G10: =IF(G$5="","",CHOOSE(G$5,KA1!$R11,KA2!$R11,KA3!$R11,KA4!$R11,KA5!$R11,KA6!$R11)) | H10: =IF(H$5="","",CHOOSE(H$5,KA1!$R11,KA2!$R11,KA3!$R11,KA4!$R11,KA5!$R11,KA6!$R11)) | I10: =IF(SUMPRODUCT(--ISNUMBER(J10:O10),$J$4:$O$4)=0,"",SUMPRODUCT(J10:O10,$J$4:$O$4)/SUMPRODUCT(--ISNUMBER(J10:O10),$J$4:$O$4)) | P10: =IF(SUMPRODUCT(--ISNUMBER(Q10:R10),$Q$4:$R$4)=0,"",SUMPRODUCT(Q10:R10,$Q$4:$R$4)/SUMPRODUCT(--ISNUMBER(Q10:R10),$Q$4:$R$4)) | Q10: =IF(Q$5="","",CHOOSE(Q$5,KA1!$R11,KA2!$R11,KA3!$R11,KA4!$R11,KA5!$R11,KA6!$R11)) | R10: =IF(R$5="","",CHOOSE(R$5,KA1!$R11,KA2!$R11,KA3!$R11,KA4!$R11,KA5!$R11,KA6!$R11)) | S10: =IF(SUMPRODUCT(--ISNUMBER(T10:Y10),$T$4:$Y$4)=0,"",SUMPRODUCT(T10:Y10,$T$4:$Y$4)/SUMPRODUCT(--ISNUMBER(T10:Y10),$T$4:$Y$4)) | Z10: =IF(((--ISNUMBER(D10))*$D$4+(--ISNUMBER(E10))*$E$4)=0,"",(IFERROR(D10*$D$4,0)+IFERROR(E10*$E$4,0))/((--ISNUMBER(D10))*$D$4+(--ISNUMBER(E10))*$E$4)) | AA10: =IF(Z10="","",ROUND(Z10,0)) | AB10: =IF(AA10="","",INDEX(Notentabelle!$B$4:$B$19,AA10+1))
A11: 5 | B11: =IF(INDEX(Klassenliste!$B$6:$B$40,5)=0,"",INDEX(Klassenliste!$B$6:$B$40,5)) | C11: =IF(INDEX(Klassenliste!$C$6:$C$40,5)=0,"",INDEX(Klassenliste!$C$6:$C$40,5)) | D11: =IF(((--ISNUMBER(F11))*$F$4+(--ISNUMBER(I11))*$I$4)=0,"",(IFERROR(F11*$F$4,0)+IFERROR(I11*$I$4,0))/((--ISNUMBER(F11))*$F$4+(--ISNUMBER(I11))*$I$4)) | E11: =IF(((--ISNUMBER(P11))*$P$4+(--ISNUMBER(S11))*$S$4)=0,"",(IFERROR(P11*$P$4,0)+IFERROR(S11*$S$4,0))/((--ISNUMBER(P11))*$P$4+(--ISNUMBER(S11))*$S$4)) | F11: =IF(SUMPRODUCT(--ISNUMBER(G11:H11),$G$4:$H$4)=0,"",SUMPRODUCT(G11:H11,$G$4:$H$4)/SUMPRODUCT(--ISNUMBER(G11:H11),$G$4:$H$4)) | G11: =IF(G$5="","",CHOOSE(G$5,KA1!$R12,KA2!$R12,KA3!$R12,KA4!$R12,KA5!$R12,KA6!$R12)) | H11: =IF(H$5="","",CHOOSE(H$5,KA1!$R12,KA2!$R12,KA3!$R12,KA4!$R12,KA5!$R12,KA6!$R12)) | I11: =IF(SUMPRODUCT(--ISNUMBER(J11:O11),$J$4:$O$4)=0,"",SUMPRODUCT(J11:O11,$J$4:$O$4)/SUMPRODUCT(--ISNUMBER(J11:O11),$J$4:$O$4)) | P11: =IF(SUMPRODUCT(--ISNUMBER(Q11:R11),$Q$4:$R$4)=0,"",SUMPRODUCT(Q11:R11,$Q$4:$R$4)/SUMPRODUCT(--ISNUMBER(Q11:R11),$Q$4:$R$4)) | Q11: =IF(Q$5="","",CHOOSE(Q$5,KA1!$R12,KA2!$R12,KA3!$R12,KA4!$R12,KA5!$R12,KA6!$R12)) | R11: =IF(R$5="","",CHOOSE(R$5,KA1!$R12,KA2!$R12,KA3!$R12,KA4!$R12,KA5!$R12,KA6!$R12)) | S11: =IF(SUMPRODUCT(--ISNUMBER(T11:Y11),$T$4:$Y$4)=0,"",SUMPRODUCT(T11:Y11,$T$4:$Y$4)/SUMPRODUCT(--ISNUMBER(T11:Y11),$T$4:$Y$4)) | Z11: =IF(((--ISNUMBER(D11))*$D$4+(--ISNUMBER(E11))*$E$4)=0,"",(IFERROR(D11*$D$4,0)+IFERROR(E11*$E$4,0))/((--ISNUMBER(D11))*$D$4+(--ISNUMBER(E11))*$E$4)) | AA11: =IF(Z11="","",ROUND(Z11,0)) | AB11: =IF(AA11="","",INDEX(Notentabelle!$B$4:$B$19,AA11+1))
A12: 6 | B12: =IF(INDEX(Klassenliste!$B$6:$B$40,6)=0,"",INDEX(Klassenliste!$B$6:$B$40,6)) | C12: =IF(INDEX(Klassenliste!$C$6:$C$40,6)=0,"",INDEX(Klassenliste!$C$6:$C$40,6)) | D12: =IF(((--ISNUMBER(F12))*$F$4+(--ISNUMBER(I12))*$I$4)=0,"",(IFERROR(F12*$F$4,0)+IFERROR(I12*$I$4,0))/((--ISNUMBER(F12))*$F$4+(--ISNUMBER(I12))*$I$4)) | E12: =IF(((--ISNUMBER(P12))*$P$4+(--ISNUMBER(S12))*$S$4)=0,"",(IFERROR(P12*$P$4,0)+IFERROR(S12*$S$4,0))/((--ISNUMBER(P12))*$P$4+(--ISNUMBER(S12))*$S$4)) | F12: =IF(SUMPRODUCT(--ISNUMBER(G12:H12),$G$4:$H$4)=0,"",SUMPRODUCT(G12:H12,$G$4:$H$4)/SUMPRODUCT(--ISNUMBER(G12:H12),$G$4:$H$4)) | G12: =IF(G$5="","",CHOOSE(G$5,KA1!$R13,KA2!$R13,KA3!$R13,KA4!$R13,KA5!$R13,KA6!$R13)) | H12: =IF(H$5="","",CHOOSE(H$5,KA1!$R13,KA2!$R13,KA3!$R13,KA4!$R13,KA5!$R13,KA6!$R13)) | I12: =IF(SUMPRODUCT(--ISNUMBER(J12:O12),$J$4:$O$4)=0,"",SUMPRODUCT(J12:O12,$J$4:$O$4)/SUMPRODUCT(--ISNUMBER(J12:O12),$J$4:$O$4)) | P12: =IF(SUMPRODUCT(--ISNUMBER(Q12:R12),$Q$4:$R$4)=0,"",SUMPRODUCT(Q12:R12,$Q$4:$R$4)/SUMPRODUCT(--ISNUMBER(Q12:R12),$Q$4:$R$4)) | Q12: =IF(Q$5="","",CHOOSE(Q$5,KA1!$R13,KA2!$R13,KA3!$R13,KA4!$R13,KA5!$R13,KA6!$R13)) | R12: =IF(R$5="","",CHOOSE(R$5,KA1!$R13,KA2!$R13,KA3!$R13,KA4!$R13,KA5!$R13,KA6!$R13)) | S12: =IF(SUMPRODUCT(--ISNUMBER(T12:Y12),$T$4:$Y$4)=0,"",SUMPRODUCT(T12:Y12,$T$4:$Y$4)/SUMPRODUCT(--ISNUMBER(T12:Y12),$T$4:$Y$4)) | Z12: =IF(((--ISNUMBER(D12))*$D$4+(--ISNUMBER(E12))*$E$4)=0,"",(IFERROR(D12*$D$4,0)+IFERROR(E12*$E$4,0))/((--ISNUMBER(D12))*$D$4+(--ISNUMBER(E12))*$E$4)) | AA12: =IF(Z12="","",ROUND(Z12,0)) | AB12: =IF(AA12="","",INDEX(Notentabelle!$B$4:$B$19,AA12+1))
A13: 7 | B13: =IF(INDEX(Klassenliste!$B$6:$B$40,7)=0,"",INDEX(Klassenliste!$B$6:$B$40,7)) | C13: =IF(INDEX(Klassenliste!$C$6:$C$40,7)=0,"",INDEX(Klassenliste!$C$6:$C$40,7)) | D13: =IF(((--ISNUMBER(F13))*$F$4+(--ISNUMBER(I13))*$I$4)=0,"",(IFERROR(F13*$F$4,0)+IFERROR(I13*$I$4,0))/((--ISNUMBER(F13))*$F$4+(--ISNUMBER(I13))*$I$4)) | E13: =IF(((--ISNUMBER(P13))*$P$4+(--ISNUMBER(S13))*$S$4)=0,"",(IFERROR(P13*$P$4,0)+IFERROR(S13*$S$4,0))/((--ISNUMBER(P13))*$P$4+(--ISNUMBER(S13))*$S$4)) | F13: =IF(SUMPRODUCT(--ISNUMBER(G13:H13),$G$4:$H$4)=0,"",SUMPRODUCT(G13:H13,$G$4:$H$4)/SUMPRODUCT(--ISNUMBER(G13:H13),$G$4:$H$4)) | G13: =IF(G$5="","",CHOOSE(G$5,KA1!$R14,KA2!$R14,KA3!$R14,KA4!$R14,KA5!$R14,KA6!$R14)) | H13: =IF(H$5="","",CHOOSE(H$5,KA1!$R14,KA2!$R14,KA3!$R14,KA4!$R14,KA5!$R14,KA6!$R14)) | I13: =IF(SUMPRODUCT(--ISNUMBER(J13:O13),$J$4:$O$4)=0,"",SUMPRODUCT(J13:O13,$J$4:$O$4)/SUMPRODUCT(--ISNUMBER(J13:O13),$J$4:$O$4)) | P13: =IF(SUMPRODUCT(--ISNUMBER(Q13:R13),$Q$4:$R$4)=0,"",SUMPRODUCT(Q13:R13,$Q$4:$R$4)/SUMPRODUCT(--ISNUMBER(Q13:R13),$Q$4:$R$4)) | Q13: =IF(Q$5="","",CHOOSE(Q$5,KA1!$R14,KA2!$R14,KA3!$R14,KA4!$R14,KA5!$R14,KA6!$R14)) | R13: =IF(R$5="","",CHOOSE(R$5,KA1!$R14,KA2!$R14,KA3!$R14,KA4!$R14,KA5!$R14,KA6!$R14)) | S13: =IF(SUMPRODUCT(--ISNUMBER(T13:Y13),$T$4:$Y$4)=0,"",SUMPRODUCT(T13:Y13,$T$4:$Y$4)/SUMPRODUCT(--ISNUMBER(T13:Y13),$T$4:$Y$4)) | Z13: =IF(((--ISNUMBER(D13))*$D$4+(--ISNUMBER(E13))*$E$4)=0,"",(IFERROR(D13*$D$4,0)+IFERROR(E13*$E$4,0))/((--ISNUMBER(D13))*$D$4+(--ISNUMBER(E13))*$E$4)) | AA13: =IF(Z13="","",ROUND(Z13,0)) | AB13: =IF(AA13="","",INDEX(Notentabelle!$B$4:$B$19,AA13+1))
A14: 8 | B14: =IF(INDEX(Klassenliste!$B$6:$B$40,8)=0,"",INDEX(Klassenliste!$B$6:$B$40,8)) | C14: =IF(INDEX(Klassenliste!$C$6:$C$40,8)=0,"",INDEX(Klassenliste!$C$6:$C$40,8)) | D14: =IF(((--ISNUMBER(F14))*$F$4+(--ISNUMBER(I14))*$I$4)=0,"",(IFERROR(F14*$F$4,0)+IFERROR(I14*$I$4,0))/((--ISNUMBER(F14))*$F$4+(--ISNUMBER(I14))*$I$4)) | E14: =IF(((--ISNUMBER(P14))*$P$4+(--ISNUMBER(S14))*$S$4)=0,"",(IFERROR(P14*$P$4,0)+IFERROR(S14*$S$4,0))/((--ISNUMBER(P14))*$P$4+(--ISNUMBER(S14))*$S$4)) | F14: =IF(SUMPRODUCT(--ISNUMBER(G14:H14),$G$4:$H$4)=0,"",SUMPRODUCT(G14:H14,$G$4:$H$4)/SUMPRODUCT(--ISNUMBER(G14:H14),$G$4:$H$4)) | G14: =IF(G$5="","",CHOOSE(G$5,KA1!$R15,KA2!$R15,KA3!$R15,KA4!$R15,KA5!$R15,KA6!$R15)) | H14: =IF(H$5="","",CHOOSE(H$5,KA1!$R15,KA2!$R15,KA3!$R15,KA4!$R15,KA5!$R15,KA6!$R15)) | I14: =IF(SUMPRODUCT(--ISNUMBER(J14:O14),$J$4:$O$4)=0,"",SUMPRODUCT(J14:O14,$J$4:$O$4)/SUMPRODUCT(--ISNUMBER(J14:O14),$J$4:$O$4)) | P14: =IF(SUMPRODUCT(--ISNUMBER(Q14:R14),$Q$4:$R$4)=0,"",SUMPRODUCT(Q14:R14,$Q$4:$R$4)/SUMPRODUCT(--ISNUMBER(Q14:R14),$Q$4:$R$4)) | Q14: =IF(Q$5="","",CHOOSE(Q$5,KA1!$R15,KA2!$R15,KA3!$R15,KA4!$R15,KA5!$R15,KA6!$R15)) | R14: =IF(R$5="","",CHOOSE(R$5,KA1!$R15,KA2!$R15,KA3!$R15,KA4!$R15,KA5!$R15,KA6!$R15)) | S14: =IF(SUMPRODUCT(--ISNUMBER(T14:Y14),$T$4:$Y$4)=0,"",SUMPRODUCT(T14:Y14,$T$4:$Y$4)/SUMPRODUCT(--ISNUMBER(T14:Y14),$T$4:$Y$4)) | Z14: =IF(((--ISNUMBER(D14))*$D$4+(--ISNUMBER(E14))*$E$4)=0,"",(IFERROR(D14*$D$4,0)+IFERROR(E14*$E$4,0))/((--ISNUMBER(D14))*$D$4+(--ISNUMBER(E14))*$E$4)) | AA14: =IF(Z14="","",ROUND(Z14,0)) | AB14: =IF(AA14="","",INDEX(Notentabelle!$B$4:$B$19,AA14+1))
A15: 9 | B15: =IF(INDEX(Klassenliste!$B$6:$B$40,9)=0,"",INDEX(Klassenliste!$B$6:$B$40,9)) | C15: =IF(INDEX(Klassenliste!$C$6:$C$40,9)=0,"",INDEX(Klassenliste!$C$6:$C$40,9)) | D15: =IF(((--ISNUMBER(F15))*$F$4+(--ISNUMBER(I15))*$I$4)=0,"",(IFERROR(F15*$F$4,0)+IFERROR(I15*$I$4,0))/((--ISNUMBER(F15))*$F$4+(--ISNUMBER(I15))*$I$4)) | E15: =IF(((--ISNUMBER(P15))*$P$4+(--ISNUMBER(S15))*$S$4)=0,"",(IFERROR(P15*$P$4,0)+IFERROR(S15*$S$4,0))/((--ISNUMBER(P15))*$P$4+(--ISNUMBER(S15))*$S$4)) | F15: =IF(SUMPRODUCT(--ISNUMBER(G15:H15),$G$4:$H$4)=0,"",SUMPRODUCT(G15:H15,$G$4:$H$4)/SUMPRODUCT(--ISNUMBER(G15:H15),$G$4:$H$4)) | G15: =IF(G$5="","",CHOOSE(G$5,KA1!$R16,KA2!$R16,KA3!$R16,KA4!$R16,KA5!$R16,KA6!$R16)) | H15: =IF(H$5="","",CHOOSE(H$5,KA1!$R16,KA2!$R16,KA3!$R16,KA4!$R16,KA5!$R16,KA6!$R16)) | I15: =IF(SUMPRODUCT(--ISNUMBER(J15:O15),$J$4:$O$4)=0,"",SUMPRODUCT(J15:O15,$J$4:$O$4)/SUMPRODUCT(--ISNUMBER(J15:O15),$J$4:$O$4)) | P15: =IF(SUMPRODUCT(--ISNUMBER(Q15:R15),$Q$4:$R$4)=0,"",SUMPRODUCT(Q15:R15,$Q$4:$R$4)/SUMPRODUCT(--ISNUMBER(Q15:R15),$Q$4:$R$4)) | Q15: =IF(Q$5="","",CHOOSE(Q$5,KA1!$R16,KA2!$R16,KA3!$R16,KA4!$R16,KA5!$R16,KA6!$R16)) | R15: =IF(R$5="","",CHOOSE(R$5,KA1!$R16,KA2!$R16,KA3!$R16,KA4!$R16,KA5!$R16,KA6!$R16)) | S15: =IF(SUMPRODUCT(--ISNUMBER(T15:Y15),$T$4:$Y$4)=0,"",SUMPRODUCT(T15:Y15,$T$4:$Y$4)/SUMPRODUCT(--ISNUMBER(T15:Y15),$T$4:$Y$4)) | Z15: =IF(((--ISNUMBER(D15))*$D$4+(--ISNUMBER(E15))*$E$4)=0,"",(IFERROR(D15*$D$4,0)+IFERROR(E15*$E$4,0))/((--ISNUMBER(D15))*$D$4+(--ISNUMBER(E15))*$E$4)) | AA15: =IF(Z15="","",ROUND(Z15,0)) | AB15: =IF(AA15="","",INDEX(Notentabelle!$B$4:$B$19,AA15+1))
A16: 10 | B16: =IF(INDEX(Klassenliste!$B$6:$B$40,10)=0,"",INDEX(Klassenliste!$B$6:$B$40,10)) | C16: =IF(INDEX(Klassenliste!$C$6:$C$40,10)=0,"",INDEX(Klassenliste!$C$6:$C$40,10)) | D16: =IF(((--ISNUMBER(F16))*$F$4+(--ISNUMBER(I16))*$I$4)=0,"",(IFERROR(F16*$F$4,0)+IFERROR(I16*$I$4,0))/((--ISNUMBER(F16))*$F$4+(--ISNUMBER(I16))*$I$4)) | E16: =IF(((--ISNUMBER(P16))*$P$4+(--ISNUMBER(S16))*$S$4)=0,"",(IFERROR(P16*$P$4,0)+IFERROR(S16*$S$4,0))/((--ISNUMBER(P16))*$P$4+(--ISNUMBER(S16))*$S$4)) | F16: =IF(SUMPRODUCT(--ISNUMBER(G16:H16),$G$4:$H$4)=0,"",SUMPRODUCT(G16:H16,$G$4:$H$4)/SUMPRODUCT(--ISNUMBER(G16:H16),$G$4:$H$4)) | G16: =IF(G$5="","",CHOOSE(G$5,KA1!$R17,KA2!$R17,KA3!$R17,KA4!$R17,KA5!$R17,KA6!$R17)) | H16: =IF(H$5="","",CHOOSE(H$5,KA1!$R17,KA2!$R17,KA3!$R17,KA4!$R17,KA5!$R17,KA6!$R17)) | I16: =IF(SUMPRODUCT(--ISNUMBER(J16:O16),$J$4:$O$4)=0,"",SUMPRODUCT(J16:O16,$J$4:$O$4)/SUMPRODUCT(--ISNUMBER(J16:O16),$J$4:$O$4)) | P16: =IF(SUMPRODUCT(--ISNUMBER(Q16:R16),$Q$4:$R$4)=0,"",SUMPRODUCT(Q16:R16,$Q$4:$R$4)/SUMPRODUCT(--ISNUMBER(Q16:R16),$Q$4:$R$4)) | Q16: =IF(Q$5="","",CHOOSE(Q$5,KA1!$R17,KA2!$R17,KA3!$R17,KA4!$R17,KA5!$R17,KA6!$R17)) | R16: =IF(R$5="","",CHOOSE(R$5,KA1!$R17,KA2!$R17,KA3!$R17,KA4!$R17,KA5!$R17,KA6!$R17)) | S16: =IF(SUMPRODUCT(--ISNUMBER(T16:Y16),$T$4:$Y$4)=0,"",SUMPRODUCT(T16:Y16,$T$4:$Y$4)/SUMPRODUCT(--ISNUMBER(T16:Y16),$T$4:$Y$4)) | Z16: =IF(((--ISNUMBER(D16))*$D$4+(--ISNUMBER(E16))*$E$4)=0,"",(IFERROR(D16*$D$4,0)+IFERROR(E16*$E$4,0))/((--ISNUMBER(D16))*$D$4+(--ISNUMBER(E16))*$E$4)) | AA16: =IF(Z16="","",ROUND(Z16,0)) | AB16: =IF(AA16="","",INDEX(Notentabelle!$B$4:$B$19,AA16+1))
A17: 11 | B17: =IF(INDEX(Klassenliste!$B$6:$B$40,11)=0,"",INDEX(Klassenliste!$B$6:$B$40,11)) | C17: =IF(INDEX(Klassenliste!$C$6:$C$40,11)=0,"",INDEX(Klassenliste!$C$6:$C$40,11)) | D17: =IF(((--ISNUMBER(F17))*$F$4+(--ISNUMBER(I17))*$I$4)=0,"",(IFERROR(F17*$F$4,0)+IFERROR(I17*$I$4,0))/((--ISNUMBER(F17))*$F$4+(--ISNUMBER(I17))*$I$4)) | E17: =IF(((--ISNUMBER(P17))*$P$4+(--ISNUMBER(S17))*$S$4)=0,"",(IFERROR(P17*$P$4,0)+IFERROR(S17*$S$4,0))/((--ISNUMBER(P17))*$P$4+(--ISNUMBER(S17))*$S$4)) | F17: =IF(SUMPRODUCT(--ISNUMBER(G17:H17),$G$4:$H$4)=0,"",SUMPRODUCT(G17:H17,$G$4:$H$4)/SUMPRODUCT(--ISNUMBER(G17:H17),$G$4:$H$4)) | G17: =IF(G$5="","",CHOOSE(G$5,KA1!$R18,KA2!$R18,KA3!$R18,KA4!$R18,KA5!$R18,KA6!$R18)) | H17: =IF(H$5="","",CHOOSE(H$5,KA1!$R18,KA2!$R18,KA3!$R18,KA4!$R18,KA5!$R18,KA6!$R18)) | I17: =IF(SUMPRODUCT(--ISNUMBER(J17:O17),$J$4:$O$4)=0,"",SUMPRODUCT(J17:O17,$J$4:$O$4)/SUMPRODUCT(--ISNUMBER(J17:O17),$J$4:$O$4)) | P17: =IF(SUMPRODUCT(--ISNUMBER(Q17:R17),$Q$4:$R$4)=0,"",SUMPRODUCT(Q17:R17,$Q$4:$R$4)/SUMPRODUCT(--ISNUMBER(Q17:R17),$Q$4:$R$4)) | Q17: =IF(Q$5="","",CHOOSE(Q$5,KA1!$R18,KA2!$R18,KA3!$R18,KA4!$R18,KA5!$R18,KA6!$R18)) | R17: =IF(R$5="","",CHOOSE(R$5,KA1!$R18,KA2!$R18,KA3!$R18,KA4!$R18,KA5!$R18,KA6!$R18)) | S17: =IF(SUMPRODUCT(--ISNUMBER(T17:Y17),$T$4:$Y$4)=0,"",SUMPRODUCT(T17:Y17,$T$4:$Y$4)/SUMPRODUCT(--ISNUMBER(T17:Y17),$T$4:$Y$4)) | Z17: =IF(((--ISNUMBER(D17))*$D$4+(--ISNUMBER(E17))*$E$4)=0,"",(IFERROR(D17*$D$4,0)+IFERROR(E17*$E$4,0))/((--ISNUMBER(D17))*$D$4+(--ISNUMBER(E17))*$E$4)) | AA17: =IF(Z17="","",ROUND(Z17,0)) | AB17: =IF(AA17="","",INDEX(Notentabelle!$B$4:$B$19,AA17+1))
A18: 12 | B18: =IF(INDEX(Klassenliste!$B$6:$B$40,12)=0,"",INDEX(Klassenliste!$B$6:$B$40,12)) | C18: =IF(INDEX(Klassenliste!$C$6:$C$40,12)=0,"",INDEX(Klassenliste!$C$6:$C$40,12)) | D18: =IF(((--ISNUMBER(F18))*$F$4+(--ISNUMBER(I18))*$I$4)=0,"",(IFERROR(F18*$F$4,0)+IFERROR(I18*$I$4,0))/((--ISNUMBER(F18))*$F$4+(--ISNUMBER(I18))*$I$4)) | E18: =IF(((--ISNUMBER(P18))*$P$4+(--ISNUMBER(S18))*$S$4)=0,"",(IFERROR(P18*$P$4,0)+IFERROR(S18*$S$4,0))/((--ISNUMBER(P18))*$P$4+(--ISNUMBER(S18))*$S$4)) | F18: =IF(SUMPRODUCT(--ISNUMBER(G18:H18),$G$4:$H$4)=0,"",SUMPRODUCT(G18:H18,$G$4:$H$4)/SUMPRODUCT(--ISNUMBER(G18:H18),$G$4:$H$4)) | G18: =IF(G$5="","",CHOOSE(G$5,KA1!$R19,KA2!$R19,KA3!$R19,KA4!$R19,KA5!$R19,KA6!$R19)) | H18: =IF(H$5="","",CHOOSE(H$5,KA1!$R19,KA2!$R19,KA3!$R19,KA4!$R19,KA5!$R19,KA6!$R19)) | I18: =IF(SUMPRODUCT(--ISNUMBER(J18:O18),$J$4:$O$4)=0,"",SUMPRODUCT(J18:O18,$J$4:$O$4)/SUMPRODUCT(--ISNUMBER(J18:O18),$J$4:$O$4)) | P18: =IF(SUMPRODUCT(--ISNUMBER(Q18:R18),$Q$4:$R$4)=0,"",SUMPRODUCT(Q18:R18,$Q$4:$R$4)/SUMPRODUCT(--ISNUMBER(Q18:R18),$Q$4:$R$4)) | Q18: =IF(Q$5="","",CHOOSE(Q$5,KA1!$R19,KA2!$R19,KA3!$R19,KA4!$R19,KA5!$R19,KA6!$R19)) | R18: =IF(R$5="","",CHOOSE(R$5,KA1!$R19,KA2!$R19,KA3!$R19,KA4!$R19,KA5!$R19,KA6!$R19)) | S18: =IF(SUMPRODUCT(--ISNUMBER(T18:Y18),$T$4:$Y$4)=0,"",SUMPRODUCT(T18:Y18,$T$4:$Y$4)/SUMPRODUCT(--ISNUMBER(T18:Y18),$T$4:$Y$4)) | Z18: =IF(((--ISNUMBER(D18))*$D$4+(--ISNUMBER(E18))*$E$4)=0,"",(IFERROR(D18*$D$4,0)+IFERROR(E18*$E$4,0))/((--ISNUMBER(D18))*$D$4+(--ISNUMBER(E18))*$E$4)) | AA18: =IF(Z18="","",ROUND(Z18,0)) | AB18: =IF(AA18="","",INDEX(Notentabelle!$B$4:$B$19,AA18+1))
A19: 13 | B19: =IF(INDEX(Klassenliste!$B$6:$B$40,13)=0,"",INDEX(Klassenliste!$B$6:$B$40,13)) | C19: =IF(INDEX(Klassenliste!$C$6:$C$40,13)=0,"",INDEX(Klassenliste!$C$6:$C$40,13)) | D19: =IF(((--ISNUMBER(F19))*$F$4+(--ISNUMBER(I19))*$I$4)=0,"",(IFERROR(F19*$F$4,0)+IFERROR(I19*$I$4,0))/((--ISNUMBER(F19))*$F$4+(--ISNUMBER(I19))*$I$4)) | E19: =IF(((--ISNUMBER(P19))*$P$4+(--ISNUMBER(S19))*$S$4)=0,"",(IFERROR(P19*$P$4,0)+IFERROR(S19*$S$4,0))/((--ISNUMBER(P19))*$P$4+(--ISNUMBER(S19))*$S$4)) | F19: =IF(SUMPRODUCT(--ISNUMBER(G19:H19),$G$4:$H$4)=0,"",SUMPRODUCT(G19:H19,$G$4:$H$4)/SUMPRODUCT(--ISNUMBER(G19:H19),$G$4:$H$4)) | G19: =IF(G$5="","",CHOOSE(G$5,KA1!$R20,KA2!$R20,KA3!$R20,KA4!$R20,KA5!$R20,KA6!$R20)) | H19: =IF(H$5="","",CHOOSE(H$5,KA1!$R20,KA2!$R20,KA3!$R20,KA4!$R20,KA5!$R20,KA6!$R20)) | I19: =IF(SUMPRODUCT(--ISNUMBER(J19:O19),$J$4:$O$4)=0,"",SUMPRODUCT(J19:O19,$J$4:$O$4)/SUMPRODUCT(--ISNUMBER(J19:O19),$J$4:$O$4)) | P19: =IF(SUMPRODUCT(--ISNUMBER(Q19:R19),$Q$4:$R$4)=0,"",SUMPRODUCT(Q19:R19,$Q$4:$R$4)/SUMPRODUCT(--ISNUMBER(Q19:R19),$Q$4:$R$4)) | Q19: =IF(Q$5="","",CHOOSE(Q$5,KA1!$R20,KA2!$R20,KA3!$R20,KA4!$R20,KA5!$R20,KA6!$R20)) | R19: =IF(R$5="","",CHOOSE(R$5,KA1!$R20,KA2!$R20,KA3!$R20,KA4!$R20,KA5!$R20,KA6!$R20)) | S19: =IF(SUMPRODUCT(--ISNUMBER(T19:Y19),$T$4:$Y$4)=0,"",SUMPRODUCT(T19:Y19,$T$4:$Y$4)/SUMPRODUCT(--ISNUMBER(T19:Y19),$T$4:$Y$4)) | Z19: =IF(((--ISNUMBER(D19))*$D$4+(--ISNUMBER(E19))*$E$4)=0,"",(IFERROR(D19*$D$4,0)+IFERROR(E19*$E$4,0))/((--ISNUMBER(D19))*$D$4+(--ISNUMBER(E19))*$E$4)) | AA19: =IF(Z19="","",ROUND(Z19,0)) | AB19: =IF(AA19="","",INDEX(Notentabelle!$B$4:$B$19,AA19+1))
